Workbook

Sheet 예산내역(사업계획서)
B1: 2026 대학혁신지원사업 예산내역 | Q1: 업데이트일 | R1: 2026.8.14 | S1: =SUBTOTAL(9,S3:S455) -> 7247118572 | U1: =SUBTOTAL(9,U2:U6868) -> 7011881940 | W1: =U1/S1 -> 0.96754067 | X1: 7247118572 | Y1: 본사업비 | Z1: 6862000000 | AA1: =S1-U1 -> 235236632
A2: 영역1 | B2: 영역 | C2: 부서 (팀명) | D2: 부서코드 | E2: 과제명 | F2: 세부과제 (드롭박스) | G2: 추진내용 (드롭박스) | H2: 추진방법 | I2: 세부추진방법 | J2: 운영내용 | K2: 한국연구재단비목 (드롭박스) | L2: 교내계정과목 (드롭박스) | M2: 계정코드 | N2: 세목 (사업단지침참고) | O2: 자금코드 | P2: 산출내역 | Q2: 산출내역 | R2: 산출내역 | S2: 최초예산 | U2: 선배정액 | V2: 차수 | W2: 배정율 | X2: =X1-S1 -> 0 | Y2: 이월금 | Z2: 385118572
A3: 교육 | B3: A | C3: 학사지원팀 | D3: =VLOOKUP(C3,코드!$E$3:$F$30,2,FALSE) -> 8634 | E3: =LEFT(F3, 5) -> [A-1] | F3: [A-1]AI기반 학사제도 다양화 | G3: 가. 전공 조합의 다양화를 통한 학사제도 고도화 | H3: 다전공 융합전공 자기설계 전공 등 제도 정비 | I3: 6개 전공 논의를 바탕으로 TFT회의 진행하여 융복합전공 개설 지원 | J3: 6개 전공조합 논의 진행(TFT) 및 융복합 전공개설 지원 | K3: 교육연구프로그램개발운영비 | L3: 기타운영비:부서별 | M3: =VLOOKUP(L3,코드!$B$3:$C$29,2,FALSE) -> 4241130 | N3: 운영비 | O3: NDZ251111 | P3: 30000 | Q3: 20 | R3: 2 | S3: 1200000 | U3: 1200000 | V3: 1차 | W3: =U3/S3 -> 1 | Z3: =SUM(Z1:Z2) -> 7247118572
A4: 교육 | B4: A | C4: 학사지원팀 | D4: =VLOOKUP(C4,코드!$E$3:$F$30,2,FALSE) -> 8634 | E4: =LEFT(F4, 5) -> [A-1] | F4: [A-1]AI기반 학사제도 다양화 | G4: 가. 전공 조합의 다양화를 통한 학사제도 고도화 | H4: 다전공 융합전공 자기설계 전공 등 제도 정비 | I4: 6개 전공 논의를 바탕으로 TFT회의 진행하여 융복합전공 개설 지원 | J4: 6개 전공조합 논의 진행 및 융복합 전공 개설 지원(교과목 개발/개선 지원) | K4: 교육연구프로그램개발운영비 | L4: 교원기타수당 | M4: =VLOOKUP(L4,코드!$B$3:$C$29,2,FALSE) -> 4113401 | N4: 교과목개발개선비 | O4: NDZ251111 | P4: 3000000 | Q4: 4 | R4: 1 | S4: 12000000 | U4: 12000000 | V4: 1차 | W4: =U4/S4 -> 1 | Z4: =U1 -> 7011881940
A5: 교육 | B5: A | C5: 학사지원팀 | D5: =VLOOKUP(C5,코드!$E$3:$F$30,2,FALSE) -> 8634 | E5: =LEFT(F5, 5) -> [A-1] | F5: [A-1]AI기반 학사제도 다양화 | G5: 가. 전공 조합의 다양화를 통한 학사제도 고도화 | H5: 다전공 융합전공 자기설계 전공 등 제도 정비 | I5: 6개 전공조합 모델별 이수 로드맵 시각화 작업 및 각 단과대학 배포 | J5: 6개 전공조합 모델별 이수 로드맵 시각화 작업 및 단과대학 배포 | K5: 교육연구프로그램개발운영비 | L5: 기타운영비:부서별 | M5: =VLOOKUP(L5,코드!$B$3:$C$29,2,FALSE) -> 4241130 | N5: 운영비 | O5: NDZ251111 | P5: 30000 | Q5: 20 | R5: 1 | S5: 600000 | U5: 600000 | V5: 7차 | W5: =U5/S5 -> 1 | Z5: =S1-U1 -> 235236632
A6: 교육 | B6: A | C6: 학사지원팀 | D6: =VLOOKUP(C6,코드!$E$3:$F$30,2,FALSE) -> 8634 | E6: =LEFT(F6, 5) -> [A-1] | F6: [A-1]AI기반 학사제도 다양화 | G6: 가. 전공 조합의 다양화를 통한 학사제도 고도화 | H6: 학생중심 전공 이수경로 제시(AI기반 조합 알고리즘 제시 및 관리) | I6: AI기반 전공 조합 알고리즘 활용 전공조합 지원(각 학과, TFT등) | J6: AI기반 전공 알고리즘 활용 전공조합 TFT | K6: 교육연구프로그램개발운영비 | L6: 기타운영비:부서별 | M6: =VLOOKUP(L6,코드!$B$3:$C$29,2,FALSE) -> 4241130 | N6: 운영비 | O6: NDZ251111 | P6: 30000 | Q6: 20 | R6: 1 | S6: 600000 | U6: 600000 | V6: 본배정 | W6: =U6/S6 -> 1
A7: 교육 | B7: A | C7: 학사지원팀 | D7: =VLOOKUP(C7,코드!$E$3:$F$30,2,FALSE) -> 8634 | E7: =LEFT(F7, 5) -> [A-1] | F7: [A-1]AI기반 학사제도 다양화 | G7: 가. 전공 조합의 다양화를 통한 학사제도 고도화 | H7: 전공조합 운영 체계화로 학생진로 맞춤 선택형 전공설계 지원 | I7: 연구보고서 기반으로 자료 정비 및 가이드라인 작성하여 단과대학 간담회 진행 | J7: 연구보고서 내용 각 단과대학과 공유 및 차기 전공조합 모델 제시 | K7: 교육연구프로그램개발운영비 | L7: 기타운영비:부서별 | M7: =VLOOKUP(L7,코드!$B$3:$C$29,2,FALSE) -> 4241130 | N7: 운영비 | O7: NDZ251111 | P7: 30000 | Q7: 30 | R7: 1 | S7: 900000 | U7: 900000 | V7: 1차 | W7: =U7/S7 -> 1 | Y7: [A-1] | Z7: =SUMIF($E$3:$E$500, Y7, S$3:S$500)/$Z$3 -> 0.0040912812 | AA7: =SUMIF($E$3:$E$500, Y7, S$3:S$500) -> 29650000 | AD7: =SUM(AA7:AB7) -> 29650000
A8: 교육 | B8: A | C8: 학사지원팀 | D8: =VLOOKUP(C8,코드!$E$3:$F$30,2,FALSE) -> 8634 | E8: =LEFT(F8, 5) -> [A-1] | F8: [A-1]AI기반 학사제도 다양화 | G8: 나. 학생중심 과목개설 및 도전학기제 도입 | H8: 온디맨드과목 및 전공개설(학생수요 반영 반응형 교과체계 도입) | I8: 학생 20명 이상 요청시 반응형으로 전공신설 학사제도 구축 | J8: 온디맨드 과목 개설 관련 회의 진행 | K8: 교육연구프로그램개발운영비 | L8: 기타운영비:부서별 | M8: =VLOOKUP(L8,코드!$B$3:$C$29,2,FALSE) -> 4241130 | N8: 운영비 | O8: NDZ251111 | P8: 30000 | Q8: 20 | R8: 1 | S8: 600000 | U8: 600000 | V8: 1차 | W8: =U8/S8 -> 1 | Y8: [A-2] | Z8: =SUMIF($E$3:$E$500, Y8, S$3:S$500)/$Z$3 -> 0.025734366 | AA8: =SUMIF($E$3:$E$500, Y8, S$3:S$500) -> 186500000 | AD8: =SUM(AA8:AB8) -> 186500000
A9: 교육 | B9: A | C9: 학사지원팀 | D9: =VLOOKUP(C9,코드!$E$3:$F$30,2,FALSE) -> 8634 | E9: =LEFT(F9, 5) -> [A-1] | F9: [A-1]AI기반 학사제도 다양화 | G9: 나. 학생중심 과목개설 및 도전학기제 도입 | H9: 온디맨드과목 및 전공개설(학생수요 반영 반응형 교과체계 도입) | I9: 학생 20명 이상 요청시 반응형으로 전공신설 학사제도 구축, 도전적 환경 조성 및 경험중심 학습기회 제공 | J9: 반응형 교과 전공개설 및 도전학기제 운영 규정 정리 | K9: 교육연구프로그램개발운영비 | L9: 기타운영비:부서별 | M9: =VLOOKUP(L9,코드!$B$3:$C$29,2,FALSE) -> 4241130 | N9: 운영비 | O9: NDZ251111 | P9: 30000 | Q9: 30 | R9: 2 | S9: 1800000 | U9: 1800000 | V9: 7차 | W9: =U9/S9 -> 1 | Y9: [A-3] | Z9: =SUMIF($E$3:$E$500, Y9, S$3:S$500)/$Z$3 -> 0.044293466 | AA9: =SUMIF($E$3:$E$500, Y9, S$3:S$500) -> 321000000 | AD9: =SUM(AA9:AB9) -> 321000000
A10: 교육 | B10: A | C10: 학사지원팀 | D10: =VLOOKUP(C10,코드!$E$3:$F$30,2,FALSE) -> 8634 | E10: =LEFT(F10, 5) -> [A-1] | F10: [A-1]AI기반 학사제도 다양화 | G10: 나. 학생중심 과목개설 및 도전학기제 도입 | H10: 온디맨드과목 및 전공개설(학생수요 반영 반응형 교과체계 도입) | I10: 반응형 교과 및 전공개설을 위한 TFT실시 | J10: 도전학기제 규정 마련 및 심화전공/심화트랙/연계전공 과정 정비 | K10: 교육연구프로그램개발운영비 | L10: 기타운영비:부서별 | M10: =VLOOKUP(L10,코드!$B$3:$C$29,2,FALSE) -> 4241130 | N10: 운영비 | O10: NDZ251111 | P10: 30000 | Q10: 15 | R10: 1 | S10: 450000 | U10: 450000 | V10: 1차 | W10: =U10/S10 -> 1 | Y10: [B-1] | Z10: =SUMIF($E$3:$E$500, Y10, S$3:S$500)/$Z$3 -> 0.053534518 | AA10: =SUMIF($E$3:$E$500, Y10, S$3:S$500) -> 387971000 | AB10: 1000000 | AC10: =AA10/SUM(AA10,AB10) -> 0.99742911 | AD10: =SUM(AA10:AB10) -> 388971000
A11: 교육 | B11: A | C11: 학사지원팀 | D11: =VLOOKUP(C11,코드!$E$3:$F$30,2,FALSE) -> 8634 | E11: =LEFT(F11, 5) -> [A-1] | F11: [A-1]AI기반 학사제도 다양화 | G11: 나. 학생중심 과목개설 및 도전학기제 도입 | H11: 지역과 세계를 캠퍼스로 하는 도전학기제 도입 | I11: 분야별(첨단, 지역사회, 스토리텔링, 창업, 글로벌협력 등) 프로젝트 수행학기 도전적 환경조성으로 적성계발 및 경험학습기회 제공 | J11: 도전학기제 사전 검증을 위한 관련부서 및 학부(과)회의 진행 | K11: 교육연구프로그램개발운영비 | L11: 기타운영비:부서별 | M11: =VLOOKUP(L11,코드!$B$3:$C$29,2,FALSE) -> 4241130 | N11: 운영비 | O11: NDZ251111 | P11: 30000 | Q11: 30 | R11: 1 | S11: 900000 | U11: 900000 | V11: 7차 | W11: =U11/S11 -> 1 | Y11: [B-2] | Z11: =SUMIF($E$3:$E$500, Y11, S$3:S$500)/$Z$3 -> 0.062786885 | AA11: =SUMIF($E$3:$E$500, Y11, S$3:S$500) -> 455024000 | AB11: 14000000 | AC11: =AA11/SUM(AA11,AB11) -> 0.97015078 | AD11: =SUM(AA11:AB11) -> 469024000
A12: 교육 | B12: A | C12: 학사지원팀 | D12: =VLOOKUP(C12,코드!$E$3:$F$30,2,FALSE) -> 8634 | E12: =LEFT(F12, 5) -> [A-1] | F12: [A-1]AI기반 학사제도 다양화 | G12: 나. 학생중심 과목개설 및 도전학기제 도입 | H12: 온디맨드과목 및 전공개설(학생수요 반영 반응형 교과체계 도입) | I12: 반응형 교과 및 전공개설을 위한 TFT실시 | J12: 도전학기제 규정 마련 및 심화전공/심화트랙/연계전공 과정 정비 | K12: 교육연구프로그램개발운영비 | L12: 교원기타수당 | M12: =VLOOKUP(L12,코드!$B$3:$C$29,2,FALSE) -> 4113401 | N12: 연구비 | O12: NDZ251111 | P12: 3000000 | Q12: 2 | R12: 1 | S12: 6000000 | U12: 6000000 | V12: 1차 | W12: =U12/S12 -> 1 | Y12: [B-3] | Z12: =SUMIF($E$3:$E$500, Y12, S$3:S$500)/$Z$3 -> 0.024198572 | AA12: =SUMIF($E$3:$E$500, Y12, S$3:S$500) -> 175369920 | AB12: 4000000 | AC12: =AA12/SUM(AA12,AB12) -> 0.97769972 | AD12: =SUM(AA12:AB12) -> 179369920
A13: 교육 | B13: A | C13: 학사지원팀 | D13: =VLOOKUP(C13,코드!$E$3:$F$30,2,FALSE) -> 8634 | E13: =LEFT(F13, 5) -> [A-1] | F13: [A-1]AI기반 학사제도 다양화 | G13: 다. 자기설계 전공 고도화 | H13: 자기설계전공 설계, 심사, 이수지원체계 구축 | I13: 제1전공 연계한 세가지 조합유형 제도화 | J13: 자기설계전공(학생설계전공) 공모전 기반 각 학부(과) 회의 | K13: 교육연구프로그램개발운영비 | L13: 기타운영비:부서별 | M13: =VLOOKUP(L13,코드!$B$3:$C$29,2,FALSE) -> 4241130 | N13: 운영비 | O13: NDZ251111 | P13: 30000 | Q13: 30 | R13: 1 | S13: 900000 | U13: 900000 | V13: 7차 | W13: =U13/S13 -> 1 | Y13: [C-1] | Z13: =SUMIF($E$3:$E$500, Y13, S$3:S$500)/$Z$3 -> 0.023416838 | AA13: =SUMIF($E$3:$E$500, Y13, S$3:S$500) -> 169704600 | AD13: =SUM(AA13:AB13) -> 169704600
A14: 교육 | B14: A | C14: 학사지원팀 | D14: =VLOOKUP(C14,코드!$E$3:$F$30,2,FALSE) -> 8634 | E14: =LEFT(F14, 5) -> [A-1] | F14: [A-1]AI기반 학사제도 다양화 | G14: 다. 자기설계 전공 고도화 | H14: 자기설계전공 설계, 심사, 이수지원체계 구축 | I14: 교과목 구성지침, 가이드, 사례집제공, 타 대학 사례 조사 등 | J14: 교과목 구성가이드 비교, 검토(타 대학 사례 분석 등) | K14: 교육연구프로그램개발운영비 | L14: 기타운영비:부서별 | M14: =VLOOKUP(L14,코드!$B$3:$C$29,2,FALSE) -> 4241130 | N14: 운영비 | O14: NDZ251111 | P14: 30000 | Q14: 30 | R14: 1 | S14: 900000 | U14: 900000 | V14: 7차 | W14: =U14/S14 -> 1 | Y14: [C-2] | Z14: =SUMIF($E$3:$E$500, Y14, S$3:S$500)/$Z$3 -> 0.065483703 | AA14: =SUMIF($E$3:$E$500, Y14, S$3:S$500) -> 474568160 | AD14: =SUM(AA14:AB14) -> 474568160
A15: 교육 | B15: A | C15: 학사지원팀 | D15: =VLOOKUP(C15,코드!$E$3:$F$30,2,FALSE) -> 8634 | E15: =LEFT(F15, 5) -> [A-1] | F15: [A-1]AI기반 학사제도 다양화 | G15: 다. 자기설계 전공 고도화 | H15: 자기설계전공 인증 및 활용도 제고 | I15: 자기설계전공 심사위원회 제도정비 심사기준마련 | J15: 자기설계전공(학생설계전공) 관련 시행세칙 및 위원회(TFT) 진행 | K15: 교육연구프로그램개발운영비 | L15: 기타운영비:부서별 | M15: =VLOOKUP(L15,코드!$B$3:$C$29,2,FALSE) -> 4241130 | N15: 운영비 | O15: NDZ251111 | P15: 30000 | Q15: 30 | R15: 1 | S15: 900000 | U15: 900000 | V15: 7차 | W15: =U15/S15 -> 1 | Y15: [C-3] | Z15: =SUMIF($E$3:$E$500, Y15, S$3:S$500)/$Z$3 -> 0.042938918 | AA15: =SUMIF($E$3:$E$500, Y15, S$3:S$500) -> 311183432 | AD15: =SUM(AA15:AB15) -> 311183432
A16: 교육 | B16: A | C16: 학사지원팀 | D16: =VLOOKUP(C16,코드!$E$3:$F$30,2,FALSE) -> 8634 | E16: =LEFT(F16, 5) -> [A-1] | F16: [A-1]AI기반 학사제도 다양화 | G16: 다. 자기설계 전공 고도화 | H16: 자기설계전공 인증 및 활용도 제고 | I16: 우수사례발굴, 홍보, 확산 및 미비점보완 활용도제고 | J16: 학생 중심 자기설계전공 구체화 지원 | K16: 교육연구프로그램개발운영비 | L16: 기타운영비:부서별 | M16: =VLOOKUP(L16,코드!$B$3:$C$29,2,FALSE) -> 4241130 | N16: 운영비 | O16: NDZ251111 | P16: 30000 | Q16: 15 | R16: 2 | S16: 900000 | U16: 900000 | V16: 7차 | W16: =U16/S16 -> 1 | Y16: [D-1] | Z16: =SUMIF($E$3:$E$500, Y16, S$3:S$500)/$Z$3 -> 0.039905515 | AA16: =SUMIF($E$3:$E$500, Y16, S$3:S$500) -> 289200000 | AB16: 62240000 | AC16: =AA16/SUM(AA16,AB16) -> 0.82290007 | AD16: =SUM(AA16:AB16) -> 351440000
A17: 교육 | B17: A | C17: 학사지원팀 | D17: =VLOOKUP(C17,코드!$E$3:$F$30,2,FALSE) -> 8634 | E17: =LEFT(F17, 5) -> [A-1] | F17: [A-1]AI기반 학사제도 다양화 | G17: 다. 자기설계 전공 고도화 | H17: 자기설계전공 인증 및 활용도 제고 | I17: 교과목 구성지침, 가이드, 사례집제공, 타 대학 사례 조사 및 우수사례발굴, 홍보, 확산 및 미비점보완 활용도제고 | J17: 교과목 구성가이드 비교, 검토(타 대학 사례 분석 등) 및 학생 중심 자기설계전공 구체화 지원을 위한 인쇄물 제작 | K17: 교육연구프로그램개발운영비 | L17: 기타운영비:부서별 | M17: =VLOOKUP(L17,코드!$B$3:$C$29,2,FALSE) -> 4241130 | N17: 운영비 | O17: NDZ251111 | P17: 1000000 | Q17: 1 | R17: 1 | S17: 1000000 | U17: 1000000 | V17: 1차 | W17: =U17/S17 -> 1 | Y17: [D-2] | Z17: =SUMIF($E$3:$E$500, Y17, S$3:S$500)/$Z$3 -> 0.012135858 | AA17: =SUMIF($E$3:$E$500, Y17, S$3:S$500) -> 87950000 | AD17: =SUM(AA17:AB17) -> 87950000
A18: 교육 | B18: A | C18: 학사지원팀 | D18: =VLOOKUP(C18,코드!$E$3:$F$30,2,FALSE) -> 8634 | E18: =LEFT(F18, 5) -> [A-2] | F18: [A-2]AI 융합 전공 혁신 | G18: 가. AI융합 공통교과목 신설 | H18: 계열별 AI전공 교과목 도입을 위한 체계수립 및 의견수렴 | I18: 계열별 AI프롬프트 활용 가이드제시 및 개발 | J18: AI 프롬프트 가이드 적용을 위한 사전 검증 진행 | K18: 교육연구프로그램개발운영비 | L18: 기타운영비:부서별 | M18: =VLOOKUP(L18,코드!$B$3:$C$29,2,FALSE) -> 4241130 | N18: 운영비 | O18: NDZ251121 | P18: 30000 | Q18: 30 | R18: 1 | S18: 900000 | U18: 900000 | V18: 본배정 | W18: =U18/S18 -> 1 | Y18: [D-3] | Z18: =SUMIF($E$3:$E$500, Y18, S$3:S$500)/$Z$3 -> 0.042377063 | AA18: =SUMIF($E$3:$E$500, Y18, S$3:S$500) -> 307111600 | AD18: =SUM(AA18:AB18) -> 307111600
A19: 교육 | B19: A | C19: 학사지원팀 | D19: =VLOOKUP(C19,코드!$E$3:$F$30,2,FALSE) -> 8634 | E19: =LEFT(F19, 5) -> [A-2] | F19: [A-2]AI 융합 전공 혁신 | G19: 가. AI융합 공통교과목 신설 | H19: 계열별 AI전공 교과목 도입을 위한 체계수립 및 의견수렴 | I19: AI담당 교수진 워크숍 및 연수 프로그램 운영 | J19: AI 교육관련 외부강사 초청 및 강의 프로그램 진행 | K19: 교육연구프로그램개발운영비 | L19: 기타운영비:부서별 | M19: =VLOOKUP(L19,코드!$B$3:$C$29,2,FALSE) -> 4241130 | N19: 전문가활용비 | O19: NDZ251121 | P19: 300000 | Q19: 2 | R19: 2 | S19: 1200000 | U19: 1200000 | W19: =U19/S19 -> 1 | Y19: [E-1] | Z19: =SUMIF($E$3:$E$500, Y19, S$3:S$500)/$Z$3 -> 0.00061679686 | AA19: =SUMIF($E$3:$E$500, Y19, S$3:S$500) -> 4470000 | AD19: =SUM(AA19:AB19) -> 4470000
A20: 교육 | B20: A | C20: 학사지원팀 | D20: =VLOOKUP(C20,코드!$E$3:$F$30,2,FALSE) -> 8634 | E20: =LEFT(F20, 5) -> [A-2] | F20: [A-2]AI 융합 전공 혁신 | G20: 가. AI융합 공통교과목 신설 | H20: AI기반 전공 매쉬업을 통한 혁신적 융합전공 개발 | I20: 수업계획서와 주차별 내용분석으로 미래예측형 융합전공개발 | J20: 연구보고서 연구 결과 기반 매쉬업 알고리즘 구성 TFT 진행 | K20: 교육연구프로그램개발운영비 | L20: 기타운영비:부서별 | M20: =VLOOKUP(L20,코드!$B$3:$C$29,2,FALSE) -> 4241130 | N20: 운영비 | O20: NDZ251121 | P20: 30000 | Q20: 20 | R20: 2 | S20: 1200000 | U20: 1200000 | V20: 1차 | W20: =U20/S20 -> 1 | Y20: [E-2] | Z20: =SUMIF($E$3:$E$500, Y20, S$3:S$500)/$Z$3 -> 0.17579963 | AA20: =SUMIF($E$3:$E$500, Y20, S$3:S$500) -> 1274040780 | AD20: =SUM(AA20:AB20) -> 1274040780
A21: 교육 | B21: A | C21: 학사지원팀 | D21: =VLOOKUP(C21,코드!$E$3:$F$30,2,FALSE) -> 8634 | E21: =LEFT(F21, 5) -> [A-2] | F21: [A-2]AI 융합 전공 혁신 | G21: 가. AI융합 공통교과목 신설 | H21: AI기반 전공 매쉬업을 통한 혁신적 융합전공 개발 | I21: 내/외부 환경 분석에 기반한 유망 AI융합전공 분야예측과 과목 및 마이크로전공 고도화 | J21: 마이크로전공 추가 개발 지원을 위한 학부(과)장 회의 진행 | K21: 교육연구프로그램개발운영비 | L21: 기타운영비:부서별 | M21: =VLOOKUP(L21,코드!$B$3:$C$29,2,FALSE) -> 4241130 | N21: 운영비 | O21: NDZ251121 | P21: 30000 | Q21: 30 | R21: 1 | S21: 900000 | U21: 900000 | V21: 본배정 | W21: =U21/S21 -> 1 | Y21: [E-3] | Z21: =SUMIF($E$3:$E$500, Y21, S$3:S$500)/$Z$3 -> 0.02099847 | AA21: =SUMIF($E$3:$E$500, Y21, S$3:S$500) -> 152178400 | AB21: 2000000 | AC21: =AA21/SUM(AA21,AB21) -> 0.98702801 | AD21: =SUM(AA21:AB21) -> 154178400
A22: 교육 | B22: A | C22: 학사지원팀 | D22: =VLOOKUP(C22,코드!$E$3:$F$30,2,FALSE) -> 8634 | E22: =LEFT(F22, 5) -> [A-2] | F22: [A-2]AI 융합 전공 혁신 | G22: 가. AI융합 공통교과목 신설 | H22: AI기반 전공 매쉬업을 통한 혁신적 융합전공 개발 | I22: 수업계획서와 주차별 내용분석으로 미래예측형 융합전공개발 | J22: 연구보고서 연구 결과 기반 매쉬업 알고리즘 구성을 위한 연구 진행 | K22: 교육연구프로그램개발운영비 | L22: 교원기타수당 | M22: =VLOOKUP(L22,코드!$B$3:$C$29,2,FALSE) -> 4113401 | N22: 연구비 | O22: NDZ251121 | P22: 3000000 | Q22: 2 | R22: 1 | S22: 6000000 | U22: 6000000 | V22: 1차 | W22: =U22/S22 -> 1 | Y22: [F-1] | Z22: =SUMIF($E$3:$E$500, Y22, S$3:S$500)/$Z$3 -> 0.011990973 | AA22: =SUMIF($E$3:$E$500, Y22, S$3:S$500) -> 86900000 | AD22: =SUM(AA22:AB22) -> 86900000
A23: 교육 | B23: A | C23: 학사지원팀 | D23: =VLOOKUP(C23,코드!$E$3:$F$30,2,FALSE) -> 8634 | E23: =LEFT(F23, 5) -> [A-2] | F23: [A-2]AI 융합 전공 혁신 | G23: 가. AI융합 공통교과목 신설 | H23: AI기반 전공 매쉬업을 통한 혁신적 융합전공 개발 | I23: 내/외부 환경 분석에 기반한 유망 AI융합전공 분야예측과 과목 및 마이크로전공 고도화 | J23: 마이크로전공 추가 개발 지원을 위한 연구보고서 작성 | K23: 교육연구프로그램개발운영비 | L23: 교원기타수당 | M23: =VLOOKUP(L23,코드!$B$3:$C$29,2,FALSE) -> 4113401 | N23: 연구비 | O23: NDZ251121 | P23: 3000000 | Q23: 2 | R23: 1 | S23: 6000000 | U23: 6000000 | V23: 1차 | W23: =U23/S23 -> 1 | Y23: [F-2] | Z23: =SUMIF($E$3:$E$500, Y23, S$3:S$500)/$Z$3 -> 0.082879461 | AA23: =SUMIF($E$3:$E$500, Y23, S$3:S$500) -> 600637280 | AB23: 80000000 | AC23: =AA23/SUM(AA23,AB23) -> 0.88246309 | AD23: =SUM(AA23:AB23) -> 680637280
A24: 교육 | B24: A | C24: 학사지원팀 | D24: =VLOOKUP(C24,코드!$E$3:$F$30,2,FALSE) -> 8634 | E24: =LEFT(F24, 5) -> [A-2] | F24: [A-2]AI 융합 전공 혁신 | G24: 나. 공통교과목 운영 고도화 | H24: 전공간 공통(Cross-listing)교과목 확대 및 체계화 | I24: 전공교육과정 분석 및 유사과목 공통교과목화 | J24: 강의시수 예산배분, 업적평가 반영 등 정책 논의 | K24: 교육연구프로그램개발운영비 | L24: 기타운영비:부서별 | M24: =VLOOKUP(L24,코드!$B$3:$C$29,2,FALSE) -> 4241130 | N24: 운영비 | O24: NDZ251121 | P24: 30000 | Q24: 30 | R24: 1 | S24: 900000 | U24: 900000 | V24: 1차 | W24: =U24/S24 -> 1 | Y24: [F-3] | Z24: =SUMIF($E$3:$E$500, Y24, S$3:S$500)/$Z$3 -> 0.0055848403 | AA24: =SUMIF($E$3:$E$500, Y24, S$3:S$500) -> 40474000 | AD24: =SUM(AA24:AB24) -> 40474000
A25: 교육 | B25: A | C25: 학사지원팀 | D25: =VLOOKUP(C25,코드!$E$3:$F$30,2,FALSE) -> 8634 | E25: =LEFT(F25, 5) -> [A-2] | F25: [A-2]AI 융합 전공 혁신 | G25: 나. 공통교과목 운영 고도화 | H25: 전공간 공통(Cross-listing)교과목 확대 및 체계화 | I25: 공통교과목 Cross-listing Gallery 플랫폼 구축 | J25: 인기강의 대형화 또는 온라인강의 전환 논의를 위한 회의 | K25: 교육연구프로그램개발운영비 | L25: 기타운영비:부서별 | M25: =VLOOKUP(L25,코드!$B$3:$C$29,2,FALSE) -> 4241130 | N25: 운영비 | O25: NDZ251121 | P25: 30000 | Q25: 30 | R25: 1 | S25: 900000 | U25: 900000 | V25: 7차 | W25: =U25/S25 -> 1 | Y25: 사업관리 | Z25: =SUMIF($E$3:$E$500, Y25, S$3:S$500)/$Z$3 -> 0.26123284 | AA25: =SUMIF($E$3:$E$500, Y25, S$3:S$500) -> 1893185400 | AD25: =SUM(AA25:AB25) -> 1893185400
A26: 교육 | B26: A | C26: 학사지원팀 | D26: =VLOOKUP(C26,코드!$E$3:$F$30,2,FALSE) -> 8634 | E26: =LEFT(F26, 5) -> [A-2] | F26: [A-2]AI 융합 전공 혁신 | G26: 나. 공통교과목 운영 고도화 | H26: 산학협력 교육강화와 산학 JA교과목 확대 | I26: 산업현장 전문가의 JA교원화로 실무인재 양성 | J26: 관련학과(JA교원 배치) 회의를 통한 방향성 수립 및 추진, A-3-가 JA교원 연구 내용 각 대학 실무자에 공유 | K26: 교육연구프로그램개발운영비 | L26: 기타운영비:부서별 | M26: =VLOOKUP(L26,코드!$B$3:$C$29,2,FALSE) -> 4241130 | N26: 운영비 | O26: NDZ251121 | P26: 30000 | Q26: 30 | R26: 1 | S26: 900000 | U26: 900000 | V26: 본배정 | W26: =U26/S26 -> 1 | Z26: =SUM(Z7:Z25) -> 1 | AD26: =SUM(AA26:AB26) -> 0
A27: 교육 | B27: A | C27: 학사지원팀 | D27: =VLOOKUP(C27,코드!$E$3:$F$30,2,FALSE) -> 8634 | E27: =LEFT(F27, 5) -> [A-2] | F27: [A-2]AI 융합 전공 혁신 | G27: 나. 공통교과목 운영 고도화 | H27: 산학협력 교육강화와 산학 JA교과목 확대 | I27: AX시대 핵심기술기업과 협력교육과정 개설 | J27: 전략적 AI, IOT, 블록체인, 메타버스 등 보유기업 니즈분석을 위한 유관부서(전공) 회의 및 협력교율과정 개설 추진 | K27: 교육연구프로그램개발운영비 | L27: 기타운영비:부서별 | M27: =VLOOKUP(L27,코드!$B$3:$C$29,2,FALSE) -> 4241130 | N27: 운영비 | O27: NDZ251121 | P27: 30000 | Q27: 20 | R27: 1 | S27: 600000 | U27: 600000 | V27: 7차 | W27: =U27/S27 -> 1
A28: 교육 | B28: A | C28: 현장실습지원센터 | D28: =VLOOKUP(C28,코드!$E$3:$F$30,2,FALSE) -> 8718 | E28: =LEFT(F28, 5) -> [A-2] | F28: [A-2]AI 융합 전공 혁신 | G28: 다. 전공 맞춤형 실무역량 강화 | H28: 캡스톤디자인 교과목 고도화 | I28: 캡스톤디자인 교과목 운영 지원 | J28: 2026학년도 캡스톤디자인 학생 물품 지원비(일반형, 기업연계형 등) | K28: 교육연구프로그램개발운영비 | L28: 기타운영비:부서별 | M28: =VLOOKUP(L28,코드!$B$3:$C$29,2,FALSE) -> 4241130 | N28: 학생교육활동지원비 | O28: NDZ251121 | P28: 200000 | Q28: 310 | R28: 2 | S28: 124000000 | U28: 124000000 | V28: 1차 | W28: =U28/S28 -> 1
A29: 교육 | B29: A | C29: 현장실습지원센터 | D29: =VLOOKUP(C29,코드!$E$3:$F$30,2,FALSE) -> 8718 | E29: =LEFT(F29, 5) -> [A-2] | F29: [A-2]AI 융합 전공 혁신 | G29: 다. 전공 맞춤형 실무역량 강화 | H29: 캡스톤디자인 교과목 고도화 | I29: 캡스톤디자인 교과목 운영 지원 | J29: 2026학년도 캡스톤디자인 교과목 운영비(소모품,인쇄제본비,회의비) | K29: 교육연구프로그램개발운영비 | L29: 기타운영비:부서별 | M29: =VLOOKUP(L29,코드!$B$3:$C$29,2,FALSE) -> 4241130 | N29: 운영비 | O29: NDZ251121 | P29: 300000 | Q29: 1 | R29: 2 | S29: 2800000 | U29: 2800000 | V29: 7차 | W29: =U29/S29 -> 1
A30: 교육 | B30: A | C30: 현장실습지원센터 | D30: =VLOOKUP(C30,코드!$E$3:$F$30,2,FALSE) -> 8718 | E30: =LEFT(F30, 5) -> [A-2] | F30: [A-2]AI 융합 전공 혁신 | G30: 다. 전공 맞춤형 실무역량 강화 | H30: 캡스톤디자인 교과목 고도화 | I30: 캡스톤디자인 교내 경진대회 운영 | J30: 2026학년도 캡스톤디자인 교내 경진대회 시상금 | K30: 장학금 | L30: 교외장학금 | M30: =VLOOKUP(L30,코드!$B$3:$C$29,2,FALSE) -> 4321701 | N30: 시상금 | O30: NDZ251125 | P30: 300000 | Q30: 10 | R30: 2 | S30: 4000000 | U30: 4000000 | V30: 본배정 | W30: =U30/S30 -> 1
A31: 교육 | B31: A | C31: 현장실습지원센터 | D31: =VLOOKUP(C31,코드!$E$3:$F$30,2,FALSE) -> 8718 | E31: =LEFT(F31, 5) -> [A-2] | F31: [A-2]AI 융합 전공 혁신 | G31: 다. 전공 맞춤형 실무역량 강화 | H31: 캡스톤디자인 교과목 고도화 | I31: 캡스톤디자인 교내 경진대회 운영 | J31: 2026학년도 캡스톤디자인 교내 경진대회 경품 | K31: 교육연구프로그램개발운영비 | L31: 기타운영비:부서별 | M31: =VLOOKUP(L31,코드!$B$3:$C$29,2,FALSE) -> 4241130 | N31: 기념품비 | O31: NDZ251121 | S31: 1000000 | U31: 1000000 | V31: 본배정 | W31: =U31/S31 -> 1
A32: 교육 | B32: A | C32: 현장실습지원센터 | D32: =VLOOKUP(C32,코드!$E$3:$F$30,2,FALSE) -> 8718 | E32: =LEFT(F32, 5) -> [A-2] | F32: [A-2]AI 융합 전공 혁신 | G32: 다. 전공 맞춤형 실무역량 강화 | H32: 캡스톤디자인 교과목 고도화 | I32: 캡스톤디자인 교내 경진대회 운영 | J32: 2026학년도 캡스톤디자인 교내 경진대회 행사 식대(도시락) | K32: 교육연구프로그램개발운영비 | L32: 기타운영비:부서별 | M32: =VLOOKUP(L32,코드!$B$3:$C$29,2,FALSE) -> 4241130 | N32: 행사비 | O32: NDZ251121 | S32: 2000000 | U32: 2000000 | V32: 본배정 | W32: =U32/S32 -> 1
A33: 교육 | B33: A | C33: 현장실습지원센터 | D33: =VLOOKUP(C33,코드!$E$3:$F$30,2,FALSE) -> 8718 | E33: =LEFT(F33, 5) -> [A-2] | F33: [A-2]AI 융합 전공 혁신 | G33: 다. 전공 맞춤형 실무역량 강화 | H33: 캡스톤디자인 교과목 고도화 | I33: 캡스톤디자인 교내 경진대회 운영 | J33: 2026학년도 캡스톤디자인 교내 경진대회 평가위원 수당 | K33: 교육연구프로그램개발운영비 | L33: 기타운영비:부서별 | M33: =VLOOKUP(L33,코드!$B$3:$C$29,2,FALSE) -> 4241130 | N33: 전문가활용비 | O33: NDZ251121 | P33: 300000 | Q33: 3 | R33: 2 | S33: 900000 | U33: 900000 | V33: 본배정 | W33: =U33/S33 -> 1
A34: 교육 | B34: A | C34: 현장실습지원센터 | D34: =VLOOKUP(C34,코드!$E$3:$F$30,2,FALSE) -> 8718 | E34: =LEFT(F34, 5) -> [A-2] | F34: [A-2]AI 융합 전공 혁신 | G34: 다. 전공 맞춤형 실무역량 강화 | H34: 캡스톤디자인 교과목 고도화 | I34: 캡스톤디자인 교내 경진대회 운영 | J34: 2026학년도 캡스톤디자인 교내 경진대회 운영비(인쇄비,소모품비,회의비) | K34: 교육연구프로그램개발운영비 | L34: 기타운영비:부서별 | M34: =VLOOKUP(L34,코드!$B$3:$C$29,2,FALSE) -> 4241130 | N34: 운영비 | O34: NDZ251121 | P34: 150000 | Q34: 1 | R34: 2 | S34: 2300000 | U34: 2300000 | V34: 본배정 | W34: =U34/S34 -> 1
A35: 교육 | B35: A | C35: 현장실습지원센터 | D35: =VLOOKUP(C35,코드!$E$3:$F$30,2,FALSE) -> 8718 | E35: =LEFT(F35, 5) -> [A-2] | F35: [A-2]AI 융합 전공 혁신 | G35: 다. 전공 맞춤형 실무역량 강화 | H35: 캡스톤디자인 교과목 고도화 | I35: 행정인력지원★ | J35: ★(전담인력 1인) 대학혁신지원사업팀 배정(이소원>최정우) | K35: 인건비 | L35: 임시직/급여 | M35: =VLOOKUP(L35,코드!$B$3:$C$29,2,FALSE) -> 4125101 | N35: 급여 | O35: NDZ251004 | S35: 30000000 | U35: 30000000 | V35: 0차 | W35: =U35/S35 -> 1
A36: 교육 | B36: A | C36: 학사지원팀 | D36: =VLOOKUP(C36,코드!$E$3:$F$30,2,FALSE) -> 8634 | E36: =LEFT(F36, 5) -> [A-3] | F36: [A-3]미래를 대비하는 데이터 기반 교육 혁신 | G36: 가. 전공 간 융합을 위한 행정지원체계 강화 | H36: 전공간 경계를 넘는 융합을 촉진하는 지원체계 구축 | I36: 행정인력지원★ | J36: ★(전담인력 1인) 대학혁신지원사업팀 배정(정승환) | K36: 인건비 | L36: 임시직/급여 | M36: =VLOOKUP(L36,코드!$B$3:$C$29,2,FALSE) -> 4125101 | N36: 급여 | O36: NDZ251004 | S36: 30000000 | U36: 30000000 | V36: 0차 | W36: =U36/S36 -> 1
A37: 교육 | B37: A | C37: 학사지원팀 | D37: =VLOOKUP(C37,코드!$E$3:$F$30,2,FALSE) -> 8634 | E37: =LEFT(F37, 5) -> [A-3] | F37: [A-3]미래를 대비하는 데이터 기반 교육 혁신 | G37: 가. 전공 간 융합을 위한 행정지원체계 강화 | H37: 전공간 경계를 넘는 융합을 촉진하는 지원체계 구축 | I37: 다전공(융복합 및 자기설계전공 등)을 위한 행정지원 신설 및 융합전공 생애주기 지원체계 구축 | J37: 융복합 전공 지원체계 추진 및 융합전공 생애주기 지원체계 구축 회의 | K37: 교육연구프로그램개발운영비 | L37: 기타운영비:부서별 | M37: =VLOOKUP(L37,코드!$B$3:$C$29,2,FALSE) -> 4241130 | N37: 운영비 | O37: NDZ251131 | P37: 30000 | Q37: 30 | R37: 1 | S37: 900000 | U37: 900000 | V37: 1차 | W37: =U37/S37 -> 1
A38: 교육 | B38: A | C38: 학사지원팀 | D38: =VLOOKUP(C38,코드!$E$3:$F$30,2,FALSE) -> 8634 | E38: =LEFT(F38, 5) -> [A-3] | F38: [A-3]미래를 대비하는 데이터 기반 교육 혁신 | G38: 가. 전공 간 융합을 위한 행정지원체계 강화 | H38: 융합전공 참여교원간 내부 JA교원 체계 구축 | I38: 융합전공 참여교원간 내부 JA교원 지정 체계 구축 | J38: A-3-가 연구보고서 내용 정리 후 공유를 통해 융합전공 참여교원 간 내부 JA 교원 지정 체계 구축 추진 | K38: 교육연구프로그램개발운영비 | L38: 기타운영비:부서별 | M38: =VLOOKUP(L38,코드!$B$3:$C$29,2,FALSE) -> 4241130 | N38: 운영비 | O38: NDZ251131 | P38: 30000 | Q38: 30 | R38: 1 | S38: 900000 | U38: 900000 | V38: 1차 | W38: =U38/S38 -> 1
A39: 교육 | B39: A | C39: 학사지원팀 | D39: =VLOOKUP(C39,코드!$E$3:$F$30,2,FALSE) -> 8634 | E39: =LEFT(F39, 5) -> [A-3] | F39: [A-3]미래를 대비하는 데이터 기반 교육 혁신 | G39: 가. 전공 간 융합을 위한 행정지원체계 강화 | H39: 수요기반 융합전공 인큐베이팅으로 확대기반 마련 | I39: 인큐베이팅 성과 창출 지원을 위한 다양한 지원방안 확보 | J39: 전공신설, 폐지, 설계전문성, 취업경쟁력 제고를 위한 협력부서 TFT 진행 | K39: 교육연구프로그램개발운영비 | L39: 기타운영비:부서별 | M39: =VLOOKUP(L39,코드!$B$3:$C$29,2,FALSE) -> 4241130 | N39: 운영비 | O39: NDZ251131 | P39: 30000 | Q39: 30 | R39: 1 | S39: 900000 | U39: 900000 | V39: 7차 | W39: =U39/S39 -> 1
A40: 교육 | B40: A | C40: 학사지원팀 | D40: =VLOOKUP(C40,코드!$E$3:$F$30,2,FALSE) -> 8634 | E40: =LEFT(F40, 5) -> [A-3] | F40: [A-3]미래를 대비하는 데이터 기반 교육 혁신 | G40: 나. 데이터 기반 전공쏠림 대응 | H40: 역동적 전공균형 시스템으로 쏠림현상 대응 | I40: 전공지원 추세분석을 기반으로 미래 전공수요 대응 | J40: 가변적 정원관리/마이크로전공/융합전공 수요분산 TFT | K40: 교육연구프로그램개발운영비 | L40: 기타운영비:부서별 | M40: =VLOOKUP(L40,코드!$B$3:$C$29,2,FALSE) -> 4241130 | N40: 운영비 | O40: NDZ251131 | P40: 30000 | Q40: 30 | R40: 1 | S40: 900000 | U40: 900000 | V40: 본배정 | W40: =U40/S40 -> 1
...

Sheet Sheet1 (2)
A3: 행 레이블 | B3: 합계 : 최초예산
A4: 교육 | B4: 4625921892
A5: 기타 | B5: 728011280
A6: 사업관리 | B6: 1893185400
A7: (비어 있음)
A8: 총합계 | B8: 7247118572

Sheet 유니올시스템업로드
A4: 합계 : 최초예산
A5: 행 레이블 | B5: 교육연구프로그램개발운영비 | C5: 실험실습장비및기자재구입비 | D5: 교육연구환경개선비 | E5: 인건비 | F5: 장학금 | G5: 그 밖의 사업운영 경비 | H5: 총합계
A6: 교육 | B6: 1731440272 | C6: 31323000 | D6: 1993231780 | E6: 517014600 | F6: 348912240 | G6: 4000000 | H6: =SUM(B6:G6) -> 4625921892
A7: 연구
A8: 기타 | B8: 581180000 | C8: 1374000 | D8: 60000000 | F8: 85457280 | H8: =SUM(B8:G8) -> 728011280
A9: 사업관리 | E9: 1197985400 | F9: 13000000 | G9: 682200000 | H9: =SUM(B9:G9) -> 1893185400
A10: 총합계 | B10: 2312620272 | C10: 32697000 | D10: 2053231780 | E10: 1715000000 | F10: 447369520 | G10: 686200000 | H10: =SUM(B10:G10) -> 7247118572
A12: 이월금
A13: 행 레이블 | B13: 교육연구프로그램개발운영비 | C13: 실험실습장비및기자재구입비 | D13: 교육연구환경개선비 | E13: 인건비 | F13: 장학금 | G13: 그 밖의 사업운영 경비 | H13: 총합계
A14: 교육 | B14: 7470000 | D14: 90000000 | E14: 0 | F14: 32600000 | H14: =SUM(B14:G14) -> 130070000
A15: 연구 | B15: 0 | E15: 0 | F15: 0 | H15: =SUM(B15:G15) -> 0
A16: 기타 | B16: 92530000 | D16: 60000000 | E16: 0 | F16: 4400000 | H16: =SUM(B16:G16) -> 156930000
A17: 사업관리 | B17: 0 | E17: 85118572 | F17: 13000000 | H17: =SUM(B17:G17) -> 98118572
A18: 총합계 | B18: =SUM(B14:B17) -> 100000000 | C18: =SUM(C14:C17) -> 0 | D18: =SUM(D14:D17) -> 150000000 | E18: =SUM(E14:E17) -> 85118572 | F18: =SUM(F14:F17) -> 50000000 | G18: =SUM(G14:G17) -> 0 | H18: =SUM(B18:G18) -> 385118572
A20: 본사업비
A21: 행 레이블 | B21: 교육연구프로그램개발운영비 | C21: 실험실습장비및기자재구입비 | D21: 교육연구환경개선비 | E21: 인건비 | F21: 장학금 | G21: 그 밖의 사업운영 경비 | H21: 총합계
A22: 교육 | B22: =B6-B14 -> 1723970272 | C22: =C6-C14 -> 31323000 | D22: =D6-D14 -> 1903231780 | E22: =E6-E14 -> 517014600 | F22: =F6-F14 -> 316312240 | G22: =G6-G14 -> 4000000 | H22: =H6-H14 -> 4495851892
A23: 연구 | B23: =B7-B15 -> 0 | C23: =C7-C15 -> 0 | D23: =D7-D15 -> 0 | E23: =E7-E15 -> 0 | F23: =F7-F15 -> 0 | G23: =G7-G15 -> 0 | H23: =H7-H15 -> 0
A24: 기타 | B24: =B8-B16 -> 488650000 | C24: =C8-C16 -> 1374000 | D24: =D8-D16 -> 0 | E24: =E8-E16 -> 0 | F24: =F8-F16 -> 81057280 | G24: =G8-G16 -> 0 | H24: =H8-H16 -> 571081280
A25: 사업관리 | B25: =B9-B17 -> 0 | C25: =C9-C17 -> 0 | D25: =D9-D17 -> 0 | E25: =E9-E17 -> 1112866828 | F25: =F9-F17 -> 0 | G25: =G9-G17 -> 682200000 | H25: =H9-H17 -> 1795066828
A26: 총합계 | B26: =SUM(B22:B25) -> 2212620272 | C26: =C10-C18 -> 32697000 | D26: =D10-D18 -> 1903231780 | E26: =E10-E18 -> 1629881428 | F26: =F10-F18 -> 397369520 | G26: =G10-G18 -> 686200000 | H26: =H10-H18 -> 6862000000

Sheet Sheet3
A3: 합계 : 최초예산 | B3: 열 레이블
A4: 행 레이블 | B4: 교육연구프로그램개발운영비 | C4: 교육연구환경개선비 | D4: 그 밖의 사업운영 경비 | E4: 실험실습장비및기자재구입비 | F4: 인건비 | G4: 장학금 | H4: (비어 있음) | I4: 총합계
A5: 교육 | B5: 1731440272 | C5: 1993231780 | D5: 4000000 | E5: 31323000 | F5: 517014600 | G5: 348912240 | H5: 0 | I5: 4625921892
A6: 기타 | B6: 581180000 | C6: 60000000 | E6: 1374000 | G6: 85457280 | I6: 728011280
A7: 사업관리 | D7: 682200000 | F7: 1197985400 | G7: 13000000 | I7: 1893185400
A8: (비어 있음)
A9: 총합계 | B9: 2312620272 | C9: 2053231780 | D9: 686200000 | E9: 32697000 | F9: 1715000000 | G9: 447369520 | H9: 0 | I9: 7247118572

Sheet 예산내역(11차배정후)
B1: 2026 대학혁신지원사업 예산내역 | P1: 업데이트일 | Q1: 2026.8.14 | R1: =SUBTOTAL(9,R3:R475) -> 7337118572 | T1: =SUBTOTAL(9,T31:T6888) -> 5721257160 | V1: =T1/R1 -> 0.77976894 | W1: 7247118572 | X1: 본사업비 | Y1: 6862000000 | Z1: =R1-T1 -> 1615861412
A2: 영역1 | B2: 영역 | C2: 부서 (팀명) | D2: 부서코드 | E2: 세부과제 (드롭박스) | F2: 추진내용 (드롭박스) | G2: 추진방법 | H2: 세부추진방법 | I2: 운영내용 | J2: 한국연구재단비목 (드롭박스) | K2: 교내계정과목 (드롭박스) | L2: 계정코드 | M2: 세목 (사업단지침참고) | N2: 자금코드 | O2: 산출내역 | P2: 산출내역 | Q2: 산출내역 | R2: 최초예산 | T2: 선배정액 | U2: 차수 | V2: 배정율 | W2: =W1-R1 -> -90000000 | X2: 이월금 | Y2: 385118572
A3: 교육 | B3: A | C3: 학사지원팀 | D3: =VLOOKUP(C3,코드!$E$3:$F$30,2,FALSE) -> 8634 | E3: [A-1]AI기반 학사제도 다양화 | F3: 가. 전공 조합의 다양화를 통한 학사제도 고도화 | G3: 다전공 융합전공 자기설계 전공 등 제도 정비 | H3: 6개 전공 논의를 바탕으로 TFT회의 진행하여 융복합전공 개설 지원 | I3: 6개 전공조합 논의 진행(TFT) 및 융복합 전공개설 지원 | J3: 교육연구프로그램개발운영비 | K3: 기타운영비:부서별 | L3: =VLOOKUP(K3,코드!$B$3:$C$29,2,FALSE) -> 4241130 | M3: 운영비 | N3: NDZ251111 | O3: 30000 | P3: 20 | Q3: 2 | R3: =O3*P3*Q3 -> 1200000 | T3: 1200000 | U3: 1차 | V3: =T3/R3 -> 1 | Y3: =SUM(Y1:Y2) -> 7247118572
A4: 교육 | B4: A | C4: 학사지원팀 | D4: =VLOOKUP(C4,코드!$E$3:$F$30,2,FALSE) -> 8634 | E4: [A-1]AI기반 학사제도 다양화 | F4: 가. 전공 조합의 다양화를 통한 학사제도 고도화 | G4: 다전공 융합전공 자기설계 전공 등 제도 정비 | H4: 6개 전공 논의를 바탕으로 TFT회의 진행하여 융복합전공 개설 지원 | I4: 6개 전공조합 논의 진행 및 융복합 전공 개설 지원(교과목 개발/개선 지원) | J4: 교육연구프로그램개발운영비 | K4: 교원기타수당 | L4: =VLOOKUP(K4,코드!$B$3:$C$29,2,FALSE) -> 4113401 | M4: 교과목개발개선비 | N4: NDZ251111 | O4: 3000000 | P4: 4 | Q4: 1 | R4: =O4*P4*Q4 -> 12000000 | T4: 12000000 | U4: 1차 | V4: =T4/R4 -> 1 | Y4: =T1 -> 5721257160
A5: 교육 | B5: A | C5: 학사지원팀 | D5: =VLOOKUP(C5,코드!$E$3:$F$30,2,FALSE) -> 8634 | E5: [A-1]AI기반 학사제도 다양화 | F5: 가. 전공 조합의 다양화를 통한 학사제도 고도화 | G5: 다전공 융합전공 자기설계 전공 등 제도 정비 | H5: 6개 전공조합 모델별 이수 로드맵 시각화 작업 및 각 단과대학 배포 | I5: 6개 전공조합 모델별 이수 로드맵 시각화 작업 및 단과대학 배포 | J5: 교육연구프로그램개발운영비 | K5: 기타운영비:부서별 | L5: =VLOOKUP(K5,코드!$B$3:$C$29,2,FALSE) -> 4241130 | M5: 운영비 | N5: NDZ251111 | O5: 30000 | P5: 20 | Q5: 1 | R5: =O5*P5*Q5 -> 600000 | T5: 600000 | U5: 7차 | V5: =T5/R5 -> 1 | Y5: =R1-T1 -> 1615861412
A6: 교육 | B6: A | C6: 학사지원팀 | D6: =VLOOKUP(C6,코드!$E$3:$F$30,2,FALSE) -> 8634 | E6: [A-1]AI기반 학사제도 다양화 | F6: 가. 전공 조합의 다양화를 통한 학사제도 고도화 | G6: 학생중심 전공 이수경로 제시(AI기반 조합 알고리즘 제시 및 관리) | H6: AI기반 전공 조합 알고리즘 활용 전공조합 지원(각 학과, TFT등) | I6: AI기반 전공 알고리즘 활용 전공조합 TFT | J6: 교육연구프로그램개발운영비 | K6: 기타운영비:부서별 | L6: =VLOOKUP(K6,코드!$B$3:$C$29,2,FALSE) -> 4241130 | M6: 운영비 | N6: NDZ251111 | O6: 30000 | P6: 20 | Q6: 1 | R6: =O6*P6*Q6 -> 600000 | T6: 0 | V6: =T6/R6 -> 0
A7: 교육 | B7: A | C7: 학사지원팀 | D7: =VLOOKUP(C7,코드!$E$3:$F$30,2,FALSE) -> 8634 | E7: [A-1]AI기반 학사제도 다양화 | F7: 가. 전공 조합의 다양화를 통한 학사제도 고도화 | G7: 전공조합 운영 체계화로 학생진로 맞춤 선택형 전공설계 지원 | H7: 연구보고서 기반으로 자료 정비 및 가이드라인 작성하여 단과대학 간담회 진행 | I7: 연구보고서 내용 각 단과대학과 공유 및 차기 전공조합 모델 제시 | J7: 교육연구프로그램개발운영비 | K7: 기타운영비:부서별 | L7: =VLOOKUP(K7,코드!$B$3:$C$29,2,FALSE) -> 4241130 | M7: 운영비 | N7: NDZ251111 | O7: 30000 | P7: 30 | Q7: 1 | R7: =O7*P7*Q7 -> 900000 | T7: 900000 | U7: 1차 | V7: =T7/R7 -> 1
A8: 교육 | B8: A | C8: 학사지원팀 | D8: =VLOOKUP(C8,코드!$E$3:$F$30,2,FALSE) -> 8634 | E8: [A-1]AI기반 학사제도 다양화 | F8: 나. 학생중심 과목개설 및 도전학기제 도입 | G8: 온디맨드과목 및 전공개설(학생수요 반영 반응형 교과체계 도입) | H8: 학생 20명 이상 요청시 반응형으로 전공신설 학사제도 구축 | I8: 온디맨드 과목 개설 관련 회의 진행 | J8: 교육연구프로그램개발운영비 | K8: 기타운영비:부서별 | L8: =VLOOKUP(K8,코드!$B$3:$C$29,2,FALSE) -> 4241130 | M8: 운영비 | N8: NDZ251111 | O8: 30000 | P8: 20 | Q8: 1 | R8: =O8*P8*Q8 -> 600000 | T8: 600000 | U8: 1차 | V8: =T8/R8 -> 1
A9: 교육 | B9: A | C9: 학사지원팀 | D9: =VLOOKUP(C9,코드!$E$3:$F$30,2,FALSE) -> 8634 | E9: [A-1]AI기반 학사제도 다양화 | F9: 나. 학생중심 과목개설 및 도전학기제 도입 | G9: 온디맨드과목 및 전공개설(학생수요 반영 반응형 교과체계 도입) | H9: 학생 20명 이상 요청시 반응형으로 전공신설 학사제도 구축, 도전적 환경 조성 및 경험중심 학습기회 제공 | I9: 반응형 교과 전공개설 및 도전학기제 운영 규정 정리 | J9: 교육연구프로그램개발운영비 | K9: 기타운영비:부서별 | L9: =VLOOKUP(K9,코드!$B$3:$C$29,2,FALSE) -> 4241130 | M9: 운영비 | N9: NDZ251111 | O9: 30000 | P9: 30 | Q9: 2 | R9: =O9*P9*Q9 -> 1800000 | T9: 1800000 | U9: 7차 | V9: =T9/R9 -> 1
A10: 교육 | B10: A | C10: 학사지원팀 | D10: =VLOOKUP(C10,코드!$E$3:$F$30,2,FALSE) -> 8634 | E10: [A-1]AI기반 학사제도 다양화 | F10: 나. 학생중심 과목개설 및 도전학기제 도입 | G10: 온디맨드과목 및 전공개설(학생수요 반영 반응형 교과체계 도입) | H10: 반응형 교과 및 전공개설을 위한 TFT실시 | I10: 도전학기제 규정 마련 및 심화전공/심화트랙/연계전공 과정 정비 | J10: 교육연구프로그램개발운영비 | K10: 기타운영비:부서별 | L10: =VLOOKUP(K10,코드!$B$3:$C$29,2,FALSE) -> 4241130 | M10: 운영비 | N10: NDZ251111 | O10: 30000 | P10: 15 | Q10: 1 | R10: =O10*P10*Q10 -> 450000 | T10: 450000 | U10: 1차 | V10: =T10/R10 -> 1
A11: 교육 | B11: A | C11: 학사지원팀 | D11: =VLOOKUP(C11,코드!$E$3:$F$30,2,FALSE) -> 8634 | E11: [A-1]AI기반 학사제도 다양화 | F11: 나. 학생중심 과목개설 및 도전학기제 도입 | G11: 지역과 세계를 캠퍼스로 하는 도전학기제 도입 | H11: 분야별(첨단, 지역사회, 스토리텔링, 창업, 글로벌협력 등) 프로젝트 수행학기 도전적 환경조성으로 적성계발 및 경험학습기회 제공 | I11: 도전학기제 사전 검증을 위한 관련부서 및 학부(과)회의 진행 | J11: 교육연구프로그램개발운영비 | K11: 기타운영비:부서별 | L11: =VLOOKUP(K11,코드!$B$3:$C$29,2,FALSE) -> 4241130 | M11: 운영비 | N11: NDZ251111 | O11: 30000 | P11: 30 | Q11: 1 | R11: =O11*P11*Q11 -> 900000 | T11: 900000 | U11: 7차 | V11: =T11/R11 -> 1
A12: 교육 | B12: A | C12: 학사지원팀 | D12: =VLOOKUP(C12,코드!$E$3:$F$30,2,FALSE) -> 8634 | E12: [A-1]AI기반 학사제도 다양화 | F12: 나. 학생중심 과목개설 및 도전학기제 도입 | G12: 온디맨드과목 및 전공개설(학생수요 반영 반응형 교과체계 도입) | H12: 반응형 교과 및 전공개설을 위한 TFT실시 | I12: 도전학기제 규정 마련 및 심화전공/심화트랙/연계전공 과정 정비 | J12: 교육연구프로그램개발운영비 | K12: 교원기타수당 | L12: =VLOOKUP(K12,코드!$B$3:$C$29,2,FALSE) -> 4113401 | M12: 연구비 | N12: NDZ251111 | O12: 3000000 | P12: 2 | Q12: 1 | R12: =O12*P12*Q12 -> 6000000 | T12: 6000000 | U12: 1차 | V12: =T12/R12 -> 1
A13: 교육 | B13: A | C13: 학사지원팀 | D13: =VLOOKUP(C13,코드!$E$3:$F$30,2,FALSE) -> 8634 | E13: [A-1]AI기반 학사제도 다양화 | F13: 다. 자기설계 전공 고도화 | G13: 자기설계전공 설계, 심사, 이수지원체계 구축 | H13: 제1전공 연계한 세가지 조합유형 제도화 | I13: 자기설계전공(학생설계전공) 공모전 기반 각 학부(과) 회의 | J13: 교육연구프로그램개발운영비 | K13: 기타운영비:부서별 | L13: =VLOOKUP(K13,코드!$B$3:$C$29,2,FALSE) -> 4241130 | M13: 운영비 | N13: NDZ251111 | O13: 30000 | P13: 30 | Q13: 1 | R13: =O13*P13*Q13 -> 900000 | T13: 900000 | U13: 7차 | V13: =T13/R13 -> 1
A14: 교육 | B14: A | C14: 학사지원팀 | D14: =VLOOKUP(C14,코드!$E$3:$F$30,2,FALSE) -> 8634 | E14: [A-1]AI기반 학사제도 다양화 | F14: 다. 자기설계 전공 고도화 | G14: 자기설계전공 설계, 심사, 이수지원체계 구축 | H14: 교과목 구성지침, 가이드, 사례집제공, 타 대학 사례 조사 등 | I14: 교과목 구성가이드 비교, 검토(타 대학 사례 분석 등) | J14: 교육연구프로그램개발운영비 | K14: 기타운영비:부서별 | L14: =VLOOKUP(K14,코드!$B$3:$C$29,2,FALSE) -> 4241130 | M14: 운영비 | N14: NDZ251111 | O14: 30000 | P14: 30 | Q14: 1 | R14: =O14*P14*Q14 -> 900000 | T14: 900000 | U14: 7차 | V14: =T14/R14 -> 1
A15: 교육 | B15: A | C15: 학사지원팀 | D15: =VLOOKUP(C15,코드!$E$3:$F$30,2,FALSE) -> 8634 | E15: [A-1]AI기반 학사제도 다양화 | F15: 다. 자기설계 전공 고도화 | G15: 자기설계전공 인증 및 활용도 제고 | H15: 자기설계전공 심사위원회 제도정비 심사기준마련 | I15: 자기설계전공(학생설계전공) 관련 시행세칙 및 위원회(TFT) 진행 | J15: 교육연구프로그램개발운영비 | K15: 기타운영비:부서별 | L15: =VLOOKUP(K15,코드!$B$3:$C$29,2,FALSE) -> 4241130 | M15: 운영비 | N15: NDZ251111 | O15: 30000 | P15: 30 | Q15: 1 | R15: =O15*P15*Q15 -> 900000 | T15: 900000 | U15: 7차 | V15: =T15/R15 -> 1
A16: 교육 | B16: A | C16: 학사지원팀 | D16: =VLOOKUP(C16,코드!$E$3:$F$30,2,FALSE) -> 8634 | E16: [A-1]AI기반 학사제도 다양화 | F16: 다. 자기설계 전공 고도화 | G16: 자기설계전공 인증 및 활용도 제고 | H16: 우수사례발굴, 홍보, 확산 및 미비점보완 활용도제고 | I16: 학생 중심 자기설계전공 구체화 지원 | J16: 교육연구프로그램개발운영비 | K16: 기타운영비:부서별 | L16: =VLOOKUP(K16,코드!$B$3:$C$29,2,FALSE) -> 4241130 | M16: 운영비 | N16: NDZ251111 | O16: 30000 | P16: 15 | Q16: 2 | R16: =O16*P16*Q16 -> 900000 | T16: 900000 | U16: 7차 | V16: =T16/R16 -> 1
A17: 교육 | B17: A | C17: 학사지원팀 | D17: =VLOOKUP(C17,코드!$E$3:$F$30,2,FALSE) -> 8634 | E17: [A-1]AI기반 학사제도 다양화 | F17: 다. 자기설계 전공 고도화 | G17: 자기설계전공 인증 및 활용도 제고 | H17: 교과목 구성지침, 가이드, 사례집제공, 타 대학 사례 조사 및 우수사례발굴, 홍보, 확산 및 미비점보완 활용도제고 | I17: 교과목 구성가이드 비교, 검토(타 대학 사례 분석 등) 및 학생 중심 자기설계전공 구체화 지원을 위한 인쇄물 제작 | J17: 교육연구프로그램개발운영비 | K17: 기타운영비:부서별 | L17: =VLOOKUP(K17,코드!$B$3:$C$29,2,FALSE) -> 4241130 | M17: 운영비 | N17: NDZ251111 | O17: 1000000 | P17: 1 | Q17: 1 | R17: =O17*P17*Q17 -> 1000000 | T17: 1000000 | U17: 1차 | V17: =T17/R17 -> 1
A19: 교육 | B19: A | C19: 학사지원팀 | D19: =VLOOKUP(C19,코드!$E$3:$F$30,2,FALSE) -> 8634 | E19: [A-2]AI 융합 전공 혁신 | F19: 가. AI융합 공통교과목 신설 | G19: 계열별 AI전공 교과목 도입을 위한 체계수립 및 의견수렴 | H19: 계열별 AI프롬프트 활용 가이드제시 및 개발 | I19: AI 프롬프트 가이드 적용을 위한 사전 검증 진행 | J19: 교육연구프로그램개발운영비 | K19: 기타운영비:부서별 | L19: =VLOOKUP(K19,코드!$B$3:$C$29,2,FALSE) -> 4241130 | M19: 운영비 | N19: NDZ251121 | O19: 30000 | P19: 30 | Q19: 1 | R19: =O19*P19*Q19 -> 900000 | T19: 0 | V19: =T19/R19 -> 0
A20: 교육 | B20: A | C20: 학사지원팀 | D20: =VLOOKUP(C20,코드!$E$3:$F$30,2,FALSE) -> 8634 | E20: [A-2]AI 융합 전공 혁신 | F20: 가. AI융합 공통교과목 신설 | G20: 계열별 AI전공 교과목 도입을 위한 체계수립 및 의견수렴 | H20: AI담당 교수진 워크숍 및 연수 프로그램 운영 | I20: AI 교육관련 외부강사 초청 및 강의 프로그램 진행 | J20: 교육연구프로그램개발운영비 | K20: 기타운영비:부서별 | L20: =VLOOKUP(K20,코드!$B$3:$C$29,2,FALSE) -> 4241130 | M20: 전문가활용비 | N20: NDZ251121 | O20: 300000 | P20: 2 | Q20: 2 | R20: =O20*P20*Q20 -> 1200000 | T20: 1200000 | V20: =T20/R20 -> 1
A21: 교육 | B21: A | C21: 학사지원팀 | D21: =VLOOKUP(C21,코드!$E$3:$F$30,2,FALSE) -> 8634 | E21: [A-2]AI 융합 전공 혁신 | F21: 가. AI융합 공통교과목 신설 | G21: AI기반 전공 매쉬업을 통한 혁신적 융합전공 개발 | H21: 수업계획서와 주차별 내용분석으로 미래예측형 융합전공개발 | I21: 연구보고서 연구 결과 기반 매쉬업 알고리즘 구성 TFT 진행 | J21: 교육연구프로그램개발운영비 | K21: 기타운영비:부서별 | L21: =VLOOKUP(K21,코드!$B$3:$C$29,2,FALSE) -> 4241130 | M21: 운영비 | N21: NDZ251121 | O21: 30000 | P21: 20 | Q21: 2 | R21: =O21*P21*Q21 -> 1200000 | T21: 1200000 | U21: 1차 | V21: =T21/R21 -> 1
A22: 교육 | B22: A | C22: 학사지원팀 | D22: =VLOOKUP(C22,코드!$E$3:$F$30,2,FALSE) -> 8634 | E22: [A-2]AI 융합 전공 혁신 | F22: 가. AI융합 공통교과목 신설 | G22: AI기반 전공 매쉬업을 통한 혁신적 융합전공 개발 | H22: 내/외부 환경 분석에 기반한 유망 AI융합전공 분야예측과 과목 및 마이크로전공 고도화 | I22: 마이크로전공 추가 개발 지원을 위한 학부(과)장 회의 진행 | J22: 교육연구프로그램개발운영비 | K22: 기타운영비:부서별 | L22: =VLOOKUP(K22,코드!$B$3:$C$29,2,FALSE) -> 4241130 | M22: 운영비 | N22: NDZ251121 | O22: 30000 | P22: 30 | Q22: 1 | R22: =O22*P22*Q22 -> 900000 | T22: 0 | V22: =T22/R22 -> 0
A23: 교육 | B23: A | C23: 학사지원팀 | D23: =VLOOKUP(C23,코드!$E$3:$F$30,2,FALSE) -> 8634 | E23: [A-2]AI 융합 전공 혁신 | F23: 가. AI융합 공통교과목 신설 | G23: AI기반 전공 매쉬업을 통한 혁신적 융합전공 개발 | H23: 수업계획서와 주차별 내용분석으로 미래예측형 융합전공개발 | I23: 연구보고서 연구 결과 기반 매쉬업 알고리즘 구성을 위한 연구 진행 | J23: 교육연구프로그램개발운영비 | K23: 교원기타수당 | L23: =VLOOKUP(K23,코드!$B$3:$C$29,2,FALSE) -> 4113401 | M23: 연구비 | N23: NDZ251121 | O23: 3000000 | P23: 2 | Q23: 1 | R23: =O23*P23*Q23 -> 6000000 | T23: 6000000 | U23: 1차 | V23: =T23/R23 -> 1
A24: 교육 | B24: A | C24: 학사지원팀 | D24: =VLOOKUP(C24,코드!$E$3:$F$30,2,FALSE) -> 8634 | E24: [A-2]AI 융합 전공 혁신 | F24: 가. AI융합 공통교과목 신설 | G24: AI기반 전공 매쉬업을 통한 혁신적 융합전공 개발 | H24: 내/외부 환경 분석에 기반한 유망 AI융합전공 분야예측과 과목 및 마이크로전공 고도화 | I24: 마이크로전공 추가 개발 지원을 위한 연구보고서 작성 | J24: 교육연구프로그램개발운영비 | K24: 교원기타수당 | L24: =VLOOKUP(K24,코드!$B$3:$C$29,2,FALSE) -> 4113401 | M24: 연구비 | N24: NDZ251121 | O24: 3000000 | P24: 2 | Q24: 1 | R24: =O24*P24*Q24 -> 6000000 | T24: 6000000 | U24: 1차 | V24: =T24/R24 -> 1
A25: 교육 | B25: A | C25: 학사지원팀 | D25: =VLOOKUP(C25,코드!$E$3:$F$30,2,FALSE) -> 8634 | E25: [A-2]AI 융합 전공 혁신 | F25: 나. 공통교과목 운영 고도화 | G25: 전공간 공통(Cross-listing)교과목 확대 및 체계화 | H25: 전공교육과정 분석 및 유사과목 공통교과목화 | I25: 강의시수 예산배분, 업적평가 반영 등 정책 논의 | J25: 교육연구프로그램개발운영비 | K25: 기타운영비:부서별 | L25: =VLOOKUP(K25,코드!$B$3:$C$29,2,FALSE) -> 4241130 | M25: 운영비 | N25: NDZ251121 | O25: 30000 | P25: 30 | Q25: 1 | R25: =O25*P25*Q25 -> 900000 | T25: 900000 | U25: 1차 | V25: =T25/R25 -> 1
A26: 교육 | B26: A | C26: 학사지원팀 | D26: =VLOOKUP(C26,코드!$E$3:$F$30,2,FALSE) -> 8634 | E26: [A-2]AI 융합 전공 혁신 | F26: 나. 공통교과목 운영 고도화 | G26: 전공간 공통(Cross-listing)교과목 확대 및 체계화 | H26: 공통교과목 Cross-listing Gallery 플랫폼 구축 | I26: 인기강의 대형화 또는 온라인강의 전환 논의를 위한 회의 | J26: 교육연구프로그램개발운영비 | K26: 기타운영비:부서별 | L26: =VLOOKUP(K26,코드!$B$3:$C$29,2,FALSE) -> 4241130 | M26: 운영비 | N26: NDZ251121 | O26: 30000 | P26: 30 | Q26: 1 | R26: =O26*P26*Q26 -> 900000 | T26: 900000 | U26: 7차 | V26: =T26/R26 -> 1
A27: 교육 | B27: A | C27: 학사지원팀 | D27: =VLOOKUP(C27,코드!$E$3:$F$30,2,FALSE) -> 8634 | E27: [A-2]AI 융합 전공 혁신 | F27: 나. 공통교과목 운영 고도화 | G27: 산학협력 교육강화와 산학 JA교과목 확대 | H27: 산업현장 전문가의 JA교원화로 실무인재 양성 | I27: 관련학과(JA교원 배치) 회의를 통한 방향성 수립 및 추진, A-3-가 JA교원 연구 내용 각 대학 실무자에 공유 | J27: 교육연구프로그램개발운영비 | K27: 기타운영비:부서별 | L27: =VLOOKUP(K27,코드!$B$3:$C$29,2,FALSE) -> 4241130 | M27: 운영비 | N27: NDZ251121 | O27: 30000 | P27: 30 | Q27: 1 | R27: =O27*P27*Q27 -> 900000 | T27: 0 | V27: =T27/R27 -> 0
A28: 교육 | B28: A | C28: 학사지원팀 | D28: =VLOOKUP(C28,코드!$E$3:$F$30,2,FALSE) -> 8634 | E28: [A-2]AI 융합 전공 혁신 | F28: 나. 공통교과목 운영 고도화 | G28: 산학협력 교육강화와 산학 JA교과목 확대 | H28: AX시대 핵심기술기업과 협력교육과정 개설 | I28: 전략적 AI, IOT, 블록체인, 메타버스 등 보유기업 니즈분석을 위한 유관부서(전공) 회의 및 협력교율과정 개설 추진 | J28: 교육연구프로그램개발운영비 | K28: 기타운영비:부서별 | L28: =VLOOKUP(K28,코드!$B$3:$C$29,2,FALSE) -> 4241130 | M28: 운영비 | N28: NDZ251121 | O28: 30000 | P28: 20 | Q28: 1 | R28: =O28*P28*Q28 -> 600000 | T28: 600000 | U28: 7차 | V28: =T28/R28 -> 1
A29: 교육 | V29: -
A30: 교육 | B30: A | C30: 현장실습지원센터 | D30: =VLOOKUP(C30,코드!$E$3:$F$30,2,FALSE) -> 8718 | E30: [A-2]AI 융합 전공 혁신 | F30: 다. 전공 맞춤형 실무역량 강화 | G30: 캡스톤디자인 교과목 고도화 | H30: 캡스톤디자인 교과목 운영 지원 | I30: 2026학년도 캡스톤디자인 학생 물품 지원비(일반형, 기업연계형 등) | J30: 교육연구프로그램개발운영비 | K30: 기타운영비:부서별 | L30: =VLOOKUP(K30,코드!$B$3:$C$29,2,FALSE) -> 4241130 | M30: 학생교육활동지원비 | N30: NDZ251121 | O30: 200000 | P30: 310 | Q30: 2 | R30: =O30*P30*Q30 -> 124000000 | T30: 124000000 | U30: 1차 | V30: =T30/R30 -> 1
A31: 교육 | B31: A | C31: 현장실습지원센터 | D31: =VLOOKUP(C31,코드!$E$3:$F$30,2,FALSE) -> 8718 | E31: [A-2]AI 융합 전공 혁신 | F31: 다. 전공 맞춤형 실무역량 강화 | G31: 캡스톤디자인 교과목 고도화 | H31: 캡스톤디자인 교과목 운영 지원 | I31: 2026학년도 캡스톤디자인 교과목 운영비(소모품,인쇄제본비,회의비) | J31: 교육연구프로그램개발운영비 | K31: 기타운영비:부서별 | L31: =VLOOKUP(K31,코드!$B$3:$C$29,2,FALSE) -> 4241130 | M31: 운영비 | N31: NDZ251121 | O31: 300000 | P31: 1 | Q31: 2 | R31: 2800000 | T31: 2800000 | U31: 7차 | V31: =T31/R31 -> 1
A32: 교육 | B32: A | C32: 현장실습지원센터 | D32: =VLOOKUP(C32,코드!$E$3:$F$30,2,FALSE) -> 8718 | E32: [A-2]AI 융합 전공 혁신 | F32: 다. 전공 맞춤형 실무역량 강화 | G32: 캡스톤디자인 교과목 고도화 | H32: 캡스톤디자인 교내 경진대회 운영 | I32: 2026학년도 캡스톤디자인 교내 경진대회 시상금 | J32: 장학금 | K32: 교외장학금 | L32: =VLOOKUP(K32,코드!$B$3:$C$29,2,FALSE) -> 4321701 | M32: 시상금 | N32: NDZ251125 | O32: 300000 | P32: 10 | Q32: 2 | R32: 4000000 | T32: 0 | V32: =T32/R32 -> 0
A33: 교육 | B33: A | C33: 현장실습지원센터 | D33: =VLOOKUP(C33,코드!$E$3:$F$30,2,FALSE) -> 8718 | E33: [A-2]AI 융합 전공 혁신 | F33: 다. 전공 맞춤형 실무역량 강화 | G33: 캡스톤디자인 교과목 고도화 | H33: 캡스톤디자인 교내 경진대회 운영 | I33: 2026학년도 캡스톤디자인 교내 경진대회 경품 | J33: 교육연구프로그램개발운영비 | K33: 기타운영비:부서별 | L33: =VLOOKUP(K33,코드!$B$3:$C$29,2,FALSE) -> 4241130 | M33: 기념품비 | N33: NDZ251121 | R33: 1000000 | V33: =T33/R33 -> 0
A34: 교육 | B34: A | C34: 현장실습지원센터 | D34: =VLOOKUP(C34,코드!$E$3:$F$30,2,FALSE) -> 8718 | E34: [A-2]AI 융합 전공 혁신 | F34: 다. 전공 맞춤형 실무역량 강화 | G34: 캡스톤디자인 교과목 고도화 | H34: 캡스톤디자인 교내 경진대회 운영 | I34: 2026학년도 캡스톤디자인 교내 경진대회 행사 식대(도시락) | J34: 교육연구프로그램개발운영비 | K34: 기타운영비:부서별 | L34: =VLOOKUP(K34,코드!$B$3:$C$29,2,FALSE) -> 4241130 | M34: 행사비 | N34: NDZ251121 | R34: 2000000 | V34: =T34/R34 -> 0
A35: 교육 | B35: A | C35: 현장실습지원센터 | D35: =VLOOKUP(C35,코드!$E$3:$F$30,2,FALSE) -> 8718 | E35: [A-2]AI 융합 전공 혁신 | F35: 다. 전공 맞춤형 실무역량 강화 | G35: 캡스톤디자인 교과목 고도화 | H35: 캡스톤디자인 교내 경진대회 운영 | I35: 2026학년도 캡스톤디자인 교내 경진대회 평가위원 수당 | J35: 교육연구프로그램개발운영비 | K35: 기타운영비:부서별 | L35: =VLOOKUP(K35,코드!$B$3:$C$29,2,FALSE) -> 4241130 | M35: 전문가활용비 | N35: NDZ251121 | O35: 300000 | P35: 3 | Q35: 2 | R35: 900000 | T35: 0 | V35: =T35/R35 -> 0
A36: 교육 | B36: A | C36: 현장실습지원센터 | D36: =VLOOKUP(C36,코드!$E$3:$F$30,2,FALSE) -> 8718 | E36: [A-2]AI 융합 전공 혁신 | F36: 다. 전공 맞춤형 실무역량 강화 | G36: 캡스톤디자인 교과목 고도화 | H36: 캡스톤디자인 교내 경진대회 운영 | I36: 2026학년도 캡스톤디자인 교내 경진대회 운영비(인쇄비,소모품비,회의비) | J36: 교육연구프로그램개발운영비 | K36: 기타운영비:부서별 | L36: =VLOOKUP(K36,코드!$B$3:$C$29,2,FALSE) -> 4241130 | M36: 운영비 | N36: NDZ251121 | O36: 150000 | P36: 1 | Q36: 2 | R36: 2300000 | T36: 0 | V36: =T36/R36 -> 0
A37: 교육 | B37: A | C37: 현장실습지원센터 | D37: =VLOOKUP(C37,코드!$E$3:$F$30,2,FALSE) -> 8718 | E37: [A-2]AI 융합 전공 혁신 | F37: 다. 전공 맞춤형 실무역량 강화 | G37: 캡스톤디자인 교과목 고도화 | H37: 행정인력지원★ | I37: ★(전담인력 1인) 대학혁신지원사업팀 배정(이소원>최정우) | J37: 인건비 | K37: 임시직/급여 | L37: =VLOOKUP(K37,코드!$B$3:$C$29,2,FALSE) -> 4125101 | M37: 급여 | N37: NDZ251004 | R37: 30000000 | T37: 30000000 | U37: 0차 | V37: =T37/R37 -> 1
A38: 교육 | V38: -
A39: 교육 | B39: A | C39: 학사지원팀 | D39: =VLOOKUP(C39,코드!$E$3:$F$30,2,FALSE) -> 8634 | E39: [A-3]미래를 대비하는 데이터 기반 교육 혁신 | F39: 가. 전공 간 융합을 위한 행정지원체계 강화 | G39: 전공간 경계를 넘는 융합을 촉진하는 지원체계 구축 | H39: 행정인력지원★ | I39: ★(전담인력 1인) 대학혁신지원사업팀 배정(정승환) | J39: 인건비 | K39: 임시직/급여 | L39: =VLOOKUP(K39,코드!$B$3:$C$29,2,FALSE) -> 4125101 | M39: 급여 | N39: NDZ251004 | R39: 30000000 | T39: 30000000 | U39: 0차 | V39: =T39/R39 -> 1
A40: 교육 | B40: A | C40: 학사지원팀 | D40: =VLOOKUP(C40,코드!$E$3:$F$30,2,FALSE) -> 8634 | E40: [A-3]미래를 대비하는 데이터 기반 교육 혁신 | F40: 가. 전공 간 융합을 위한 행정지원체계 강화 | G40: 전공간 경계를 넘는 융합을 촉진하는 지원체계 구축 | H40: 다전공(융복합 및 자기설계전공 등)을 위한 행정지원 신설 및 융합전공 생애주기 지원체계 구축 | I40: 융복합 전공 지원체계 추진 및 융합전공 생애주기 지원체계 구축 회의 | J40: 교육연구프로그램개발운영비 | K40: 기타운영비:부서별 | L40: =VLOOKUP(K40,코드!$B$3:$C$29,2,FALSE) -> 4241130 | M40: 운영비 | N40: NDZ251131 | O40: 30000 | P40: 30 | Q40: 1 | R40: =O40*P40*Q40 -> 900000 | T40: 900000 | U40: 1차 | V40: =T40/R40 -> 1
A41: 교육 | B41: A | C41: 학사지원팀 | D41: =VLOOKUP(C41,코드!$E$3:$F$30,2,FALSE) -> 8634 | E41: [A-3]미래를 대비하는 데이터 기반 교육 혁신 | F41: 가. 전공 간 융합을 위한 행정지원체계 강화 | G41: 융합전공 참여교원간 내부 JA교원 체계 구축 | H41: 융합전공 참여교원간 내부 JA교원 지정 체계 구축 | I41: A-3-가 연구보고서 내용 정리 후 공유를 통해 융합전공 참여교원 간 내부 JA 교원 지정 체계 구축 추진 | J41: 교육연구프로그램개발운영비 | K41: 기타운영비:부서별 | L41: =VLOOKUP(K41,코드!$B$3:$C$29,2,FALSE) -> 4241130 | M41: 운영비 | N41: NDZ251131 | O41: 30000 | P41: 30 | Q41: 1 | R41: =O41*P41*Q41 -> 900000 | T41: 900000 | U41: 1차 | V41: =T41/R41 -> 1
...

Sheet 인건비계획
B1: 2026년 혁신지원사업 인건비 운영계획(안)
H2: 2026.3.24. 기준
B3: 부서 | C3: 구분 | D3: 인원 | E3: 비고 | F3: 연봉 | G3: 합계 | H3: 비고 | J3: 김희도
B4: 사업단 | C4: 행정인력 | D4: 4 | F4: 31200000 | G4: =D4*F4 -> 124800000 | H4: 2년차(4,6,7월) | J4: 이경희 | K4: 4 | L4: 송지수 | N4: 20260811 | P4: 300000000
B5: RC | C5: 행정인력 | D5: 2 | F5: 30000000 | G5: =D5*F5 -> 60000000 | J5: 장치완 | K5: 4 | L5: 이순용
C6: 교육전문연구원 | D6: 2 | E6: 석사급 | F6: 34968600 | G6: =D6*F6 -> 69937200 | J6: 송지수 | K6: 4 | L6: 박세영
C7: 교육전문연구원 | D7: 1 | E7: 박사급 | F7: 38018400 | G7: =D7*F7 -> 38018400 | H7: 사고 | J7: 김승환 | K7: 6 | L7: 감원정
B8: 미래융합교육혁신원 | C8: 행정인력 | D8: 1 | F8: 31200000 | G8: =D8*F8 -> 31200000 | H8: 2년차(4월) | J8: 김민영 | K8: 6 | L8: 맹현주
C9: 교육전문연구원 | D9: 2 | E9: 석사급 | F9: 34968600 | G9: =D9*F9 -> 69937200 | H9: 2년차(4월) | J9: 권의정 | K9: 7 | L9: 임성환
B10: IR센터 | C10: 행정인력 | D10: 1 | F10: 30000000 | G10: =D10*F10 -> 30000000 | H10: 2년차(12월) | J10: 박세영 | K10: 8 | L10: 정소라
C11: 교육전문연구원 | D11: 1 | E11: 석사급 | F11: 34968600 | G11: =D11*F11 -> 34968600
C12: 교육전문연구원 | D12: 1 | E12: 박사급 | F12: 38018400 | G12: =D12*F12 -> 38018400
B13: 학사지원팀 | C13: 행정인력 | D13: 1 | F13: 30000000 | G13: =D13*F13 -> 30000000 | H13: 2년차(12월)
B14: 경력개발팀 | C14: 행정인력 | D14: 2 | F14: 31200000 | G14: =D14*F14 -> 62400000 | H14: 2년차(9월)
B15: 현장실습지원센터 | C15: 행정인력 | D15: 1 | F15: 30000000 | G15: =D15*F15 -> 30000000
B16: 심리상담센터 | C16: 행정인력 | D16: 1 | F16: 31200000 | G16: =D16*F16 -> 31200000 | H16: 2년차(6월)
B17: 퇴직급여충당금(연봉/12) | D17: 20명 | G17: =SUM(G4:G16)/12 -> 54206650
B18: 법인부담금(11.2%) | D18: 20명 | G18: =SUM(G4:G16)*11.2% -> 72853738
B19: 시간외수당(기존교직원 포함) | G19: 35000000
B20: 인센티브 | C20: 신규교직원 | D20: 20명 | G20: 60000000
C21: 기존교직원 | D21: 40명 | G21: 70000000 | H21: 감액
B22: 합계 | G22: =SUM(G4:G21) -> 9.4254019e+08
B24: 구분 | C24: 인원 | E24: 구분 | F24: 2025년 | G24: 2026년(예상)
B25: 행정인력 | C25: =SUMIFS(D4:D16,C4:C16,B25) -> 13 | E25: 총사업비 | F25: 7663000000 | G25: 6862000000
B26: 교육전문연구원 | C26: =SUMIFS(D4:D16,C4:C16,B26) -> 7 | E26: 인건비예산(25%) | F26: 1915750000 | G26: =G25*25% -> 1715500000 | H26: 본사업비25%
B27: 합계 | C27: =SUM(C25:C26) -> 20 | E27: 신규교직원 | F27: 486245331
B28: ※ 2026.3.24.일자 17명 충원(RC1명/미융원1명/IR센터1명 결원) | E28: 기존교직원지원 | F28: 1412881580
E29: 집행액 | F29: =SUM(F27:F28) -> 1899126911
E30: 1. 2025년 미충원 상태 운영하여 4.8억 수준 운영
E31: 2. 학사지도사 급여 기존교직원→신규교직원이동(학사지도사3명/PBS1명)
E32: 3. 신규교직원 예산에 기존교직원 인센티브 지급액 포함
E33: 4. 인수인계로 인한 중복근로기간, 미충원공백등 차액발생가능

Sheet 코드
B2: 계정과목명 | C2: 코드 | E2: 예산부서내역 | F2: 예산부서 | H2: 세부과제 | J2: 추진내용 | M2: 구분 | N2: 비목 | O2: 과제번호 | P2: 고유번호 | Q2: 영역 | R2: 과제번호 | S2: 비목 | T2: 자금코드 | U2: 자금코드명 | V2: 과제 | W2: 비고
B3: 실험실습비/학부 | C3: 4323101 | E3: 치위생학과 | F3: 2805 | H3: [A-1]AI기반 학사제도 다양화 | J3: 가. 전공 조합의 다양화를 통한 학사제도 고도화 | M3: 혁신 | N3: 교육연구프로그램개발운영비 | O3: A-1 | P3: 251 | Q3: 1 | R3: 1 | S3: 1 | T3: ="NDZ251"&Q3&R3&S3 -> NDZ251111 | U3: 혁신A-1교육연구프로그램개발운영비 | V3: [A-1]AI기반 학사제도 다양화
B4: 교외장학금 | C4: 4321701 | E4: 임상병리학 | F4: 2903 | H4: [A-2]AI 융합 전공 혁신 | J4: 나. 학생중심 과목개설 및 도전학기제 도입 | M4: 혁신 | N4: 실험실습장비및기자재구입비 | O4: A-1 | P4: 251 | Q4: 1 | R4: 1 | S4: 2 | T4: ="NDZ251"&Q4&R4&S4 -> NDZ251112 | U4: 혁신A-1실험실습장비및기자재구입비 | V4: [A-1]AI기반 학사제도 다양화
B5: 기타운영비:부서별 | C5: 4241130 | E5: 물리치료학과 | F5: 2916 | H5: [A-3]미래를 대비하는 데이터 기반 교육 혁신 | J5: 다. 자기설계 전공 고도화 | M5: 혁신 | N5: 교육연구환경개선비 | O5: A-1 | P5: 251 | Q5: 1 | R5: 1 | S5: 3 | T5: ="NDZ251"&Q5&R5&S5 -> NDZ251113 | U5: 혁신A-1교육연구환경개선비 | V5: [A-1]AI기반 학사제도 다양화
B6: 업무용기계기구구입지출 | C6: 1314903 | E6: 작업치료학과 | F6: 2917 | H6: [B-1]학생 성공 AI에듀가이드 고도화 | J6: 가. AI융합 공통교과목 신설 | M6: 혁신 | N6: 인건비 | O6: A-1 | P6: 251 | Q6: 1 | R6: 1 | S6: 4 | T6: ="NDZ251"&Q6&R6&S6 -> NDZ251114 | U6: 혁신A-1인건비 | V6: [A-1]AI기반 학사제도 다양화 | W6: 부서사용불가
B7: 업무용비품구입지출 | C7: 1315903 | E7: 정경대학원 | F7: 7810 | H7: [B-2]AI 온디맨드 경력개발 지원체계 구축 | J7: 나. 공통교과목 운영 고도화 | M7: 혁신 | N7: 장학금 | O7: A-1 | P7: 251 | Q7: 1 | R7: 1 | S7: 5 | T7: ="NDZ251"&Q7&R7&S7 -> NDZ251115 | U7: 혁신A-1장학금 | V7: [A-1]AI기반 학사제도 다양화
B8: 교원기타수당 | C8: 4113401 | E8: 일반대학원 | F8: 7840 | H8: [B-3]마음건강 마이크로케어 플랫폼 고도화 | J8: 다. 전공 맞춤형 실무역량 강화 | M8: 혁신 | N8: 그 밖의 사업운영 경비 | O8: A-1 | P8: 251 | Q8: 1 | R8: 1 | S8: 6 | T8: ="NDZ251"&Q8&R8&S8 -> NDZ251116 | U8: 혁신A-1그 밖의 사업운영 경비 | V8: [A-1]AI기반 학사제도 다양화 | W8: 부서사용불가
B9: 행정사무직수당:부서 | C9: 4123802 | E9: 혁신전략기획팀 | F9: 8621 | H9: [C-1]AI 기반 교육과정 혁신 및 수업모델 개발 | J9: 가. 전공 간 융합을 위한 행정지원체계 강화 | M9: 혁신 | N9: 교육연구프로그램개발운영비 | O9: A-2 | P9: 251 | Q9: 1 | R9: 2 | S9: 1 | T9: ="NDZ251"&Q9&R9&S9 -> NDZ251121 | U9: 혁신A-2교육연구프로그램개발운영비 | V9: [A-2]AI 융합 전공 혁신
B10: 교원기타수당 | C10: 4113401 | E10: IR센터 | F10: 8623 | H10: [C-2]AI-Edutech 기반 교수-학습 역량 강화 | J10: 나. 데이터 기반 전공쏠림 대응 | M10: 혁신 | N10: 실험실습장비및기자재구입비 | O10: A-2 | P10: 251 | Q10: 1 | R10: 2 | S10: 2 | T10: ="NDZ251"&Q10&R10&S10 -> NDZ251122 | U10: 혁신A-2실험실습장비및기자재구입비 | V10: [A-2]AI 융합 전공 혁신
B11: 건축물관리비:기타 | C11: 4211402 | E11: 대외협력팀 | F11: 8627 | H11: [C-3]AI-Data 기반 교육과정 성과 관리 | J11: 다. 데이터 기반 유연학사제도 고도화 | M11: 혁신 | N11: 교육연구환경개선비 | O11: A-2 | P11: 251 | Q11: 1 | R11: 2 | S11: 3 | T11: ="NDZ251"&Q11&R11&S11 -> NDZ251123 | U11: 혁신A-2교육연구환경개선비 | V11: [A-2]AI 융합 전공 혁신
B12: 기타학생경비:부서별 | C12: 4329701 | E12: 교무팀 | F12: 8631 | H12: [D-1]포용과 통합의 RC실천교육 모델 | J12: 가. AI 기능 고도화 및 통합 AI에듀가이드 제공 | M12: 혁신 | N12: 인건비 | O12: A-2 | P12: 251 | Q12: 1 | R12: 2 | S12: 4 | T12: ="NDZ251"&Q12&R12&S12 -> NDZ251124 | U12: 혁신A-2인건비 | V12: [A-2]AI 융합 전공 혁신 | W12: 부서사용불가
B13: 전기수도료:전기료 | C13: 4226101 | E13: 학사지원팀 | F13: 8634 | H13: [D-2]진단-맞춤형 기초학습 생태계 구축 | J13: 나. 사용자 편의성을 확대한 AI에듀가이드 구현 | M13: 혁신 | N13: 장학금 | O13: A-2 | P13: 251 | Q13: 1 | R13: 2 | S13: 5 | T13: ="NDZ251"&Q13&R13&S13 -> NDZ251125 | U13: 혁신A-2장학금 | V13: [A-2]AI 융합 전공 혁신
B14: 교육용기계기구구입지출 | C14: 1314901 | E14: RC융합대학 | F14: 8639 | H14: [D-3]데이터기반 자기주도 전공진로 설계 지원 | J14: 다. 학생 성공 선순환 고리 형성 | M14: 혁신 | N14: 그 밖의 사업운영 경비 | O14: A-2 | P14: 251 | Q14: 1 | R14: 2 | S14: 6 | T14: ="NDZ251"&Q14&R14&S14 -> NDZ251126 | U14: 혁신A-2그 밖의 사업운영 경비 | V14: [A-2]AI 융합 전공 혁신 | W14: 부서사용불가
B15: 특별강의료:특별강의료 | C15: 4116101 | E15: 학생지원팀 | F15: 8641 | H15: [E-1]교원 인사제도 및 학과평가 체계 개선 | J15: 가. AI기반 진로·취업 지원을 위한 경력개발 데이터 구축 | M15: 혁신 | N15: 교육연구프로그램개발운영비 | O15: A-3 | P15: 251 | Q15: 1 | R15: 3 | S15: 1 | T15: ="NDZ251"&Q15&R15&S15 -> NDZ251131 | U15: 혁신A-3교육연구프로그램개발운영비 | V15: [A-3]미래를 대비하는 데이터 기반 교육 혁신
B16: 비전임교원보험통합 | C16: 4118509 | E16: 심리상담센터 | F16: 8647 | H16: [E-2]디지털 기반 교육자원 재구조화 | J16: 나. 온디맨드 경력개발 서비스 운영 | M16: 혁신 | N16: 실험실습장비및기자재구입비 | O16: A-3 | P16: 251 | Q16: 1 | R16: 3 | S16: 2 | T16: ="NDZ251"&Q16&R16&S16 -> NDZ251132 | U16: 혁신A-3실험실습장비및기자재구입비 | V16: [A-3]미래를 대비하는 데이터 기반 교육 혁신
B17: 임시직/급여:보험통합 | C17: 4125509 | E17: 인사총무팀 | F17: 8651 | H17: [E-3]실시간 성과 분석 환류 IR시스템 구축 | J17: 다. AI 온디맨드 경력개발 성과관리 | M17: 혁신 | N17: 교육연구환경개선비 | O17: A-3 | P17: 251 | Q17: 1 | R17: 3 | S17: 3 | T17: ="NDZ251"&Q17&R17&S17 -> NDZ251133 | U17: 혁신A-3교육연구환경개선비 | V17: [A-3]미래를 대비하는 데이터 기반 교육 혁신
B18: 일반용역비:부서별 | C18: 4233201 | E18: 인권센터 | F18: 8655 | H18: [F-1]지역대학 공유·협력 활성화 및 성과 확산 | J18: 가.마음건강 진단 및 예방체계 활성화 | M18: 혁신 | N18: 인건비 | O18: A-3 | P18: 251 | Q18: 1 | R18: 3 | S18: 4 | T18: ="NDZ251"&Q18&R18&S18 -> NDZ251134 | U18: 혁신A-3인건비 | V18: [A-3]미래를 대비하는 데이터 기반 교육 혁신 | W18: 부서사용불가
B19: 기타운영비:부서별 | C19: 4241130 | E19: 시설관리팀 | F19: 8671 | H19: [F-2]스마트 ESG 캠퍼스 조성 | J19: 나. 다양성 존중 마이크로케어 지원체계 구축 | M19: 혁신 | N19: 장학금 | O19: A-3 | P19: 251 | Q19: 1 | R19: 3 | S19: 5 | T19: ="NDZ251"&Q19&R19&S19 -> NDZ251135 | U19: 혁신A-3장학금 | V19: [A-3]미래를 대비하는 데이터 기반 교육 혁신
B20: 교원급여/본봉 | C20: 4111101 | E20: 안전관리팀 | F20: 8673 | H20: [F-3]지속가능한 발전을 위한 글로벌 사회 혁신 | J20: 다. 캠퍼스-지역사회 협력 마이크로케어 확산 | M20: 혁신 | N20: 그 밖의 사업운영 경비 | O20: A-3 | P20: 251 | Q20: 1 | R20: 3 | S20: 6 | T20: ="NDZ251"&Q20&R20&S20 -> NDZ251136 | U20: 혁신A-3그 밖의 사업운영 경비 | V20: [A-3]미래를 대비하는 데이터 기반 교육 혁신 | W20: 부서사용불가
B21: 비전임교원인건비 | C21: 4118701 | E21: 정보통신팀 | F21: 8693 | H21: 사업관리 및 운영 | J21: 가. AX 시대 역량기반 전공교육과정 혁신 | M21: 혁신 | N21: 교육연구프로그램개발운영비 | O21: B-1 | P21: 251 | Q21: 2 | R21: 1 | S21: 1 | T21: ="NDZ251"&Q21&R21&S21 -> NDZ251211 | U21: 혁신B-1교육연구프로그램개발운영비 | V21: [B-1]학생 성공 AI에듀가이드 고도화
B22: 비전임교원수당 | C22: 4118702 | E22: 미래융합교육혁신원 | F22: 8701 | J22: 나. AI 기반 전공 선택 지원 및 융합전공 확대 | M22: 혁신 | N22: 실험실습장비및기자재구입비 | O22: B-1 | P22: 251 | Q22: 2 | R22: 1 | S22: 2 | T22: ="NDZ251"&Q22&R22&S22 -> NDZ251212 | U22: 혁신B-1실험실습장비및기자재구입비 | V22: [B-1]학생 성공 AI에듀가이드 고도화
B23: 직원제수당:시간외수당 | C23: 4123301 | E23: 창업교육센터 | F23: 8710 | J23: 다. 현장·경험 기반 6P 혁신 수업모델 개발 | M23: 혁신 | N23: 교육연구환경개선비 | O23: B-1 | P23: 251 | Q23: 2 | R23: 1 | S23: 3 | T23: ="NDZ251"&Q23&R23&S23 -> NDZ251213 | U23: 혁신B-1교육연구환경개선비 | V23: [B-1]학생 성공 AI에듀가이드 고도화
B24: 행정사무직 수당 | C24: 4123801 | E24: 경력개발팀 | F24: 8711 | J24: 가. AI-Edutech 기반 교수자 수업 혁신 지원 | M24: 혁신 | N24: 인건비 | O24: B-1 | P24: 251 | Q24: 2 | R24: 1 | S24: 4 | T24: ="NDZ251"&Q24&R24&S24 -> NDZ251214 | U24: 혁신B-1인건비 | V24: [B-1]학생 성공 AI에듀가이드 고도화 | W24: 부서사용불가
B25: 임시직/급여 | C25: 4125101 | E25: 진로교육센터 | F25: 8714 | J25: 나. AI-Edutech 기반 학생성공(학습분야) 지원 | M25: 혁신 | N25: 장학금 | O25: B-1 | P25: 251 | Q25: 2 | R25: 1 | S25: 5 | T25: ="NDZ251"&Q25&R25&S25 -> NDZ251215 | U25: 혁신B-1장학금 | V25: [B-1]학생 성공 AI에듀가이드 고도화
B26: 임시직/수당 | C26: 4125301 | E26: 머레이봉사센터 | F26: 8717 | J26: 다. 교수-학습 개선 성과 확산 및 지속가능 시스템 강화 | M26: 혁신 | N26: 그 밖의 사업운영 경비 | O26: B-1 | P26: 251 | Q26: 2 | R26: 1 | S26: 6 | T26: ="NDZ251"&Q26&R26&S26 -> NDZ251216 | U26: 혁신B-1그 밖의 사업운영 경비 | V26: [B-1]학생 성공 AI에듀가이드 고도화 | W26: 부서사용불가
B27: 임시직수당:부서별 | C27: 4125302 | E27: 현장실습지원센터 | F27: 8718 | J27: 가. AI·데이터 기반 교과교육과정의 적합성 및 품질관리 | M27: 혁신 | N27: 교육연구프로그램개발운영비 | O27: B-2 | P27: 251 | Q27: 2 | R27: 2 | S27: 1 | T27: ="NDZ251"&Q27&R27&S27 -> NDZ251221 | U27: 혁신B-2교육연구프로그램개발운영비 | V27: [B-2]AI 온디맨드 경력개발 지원체계 구축
B28: 직원퇴직:임시직퇴직 | C28: 4125602 | E28: 미래대학혁신지원사업단 | F28: 8719 | J28: 나. AI·데이터 기반 ECA프로그램 통합 및 성과 관리 | M28: 혁신 | N28: 실험실습장비및기자재구입비 | O28: B-2 | P28: 251 | Q28: 2 | R28: 2 | S28: 2 | T28: ="NDZ251"&Q28&R28&S28 -> NDZ251222 | U28: 혁신B-2실험실습장비및기자재구입비 | V28: [B-2]AI 온디맨드 경력개발 지원체계 구축
B29: 기타 | C29: 기타 | E29: 미래평생교육원 | F29: 8725 | J29: 다. AI·데이터 기반 초개인화 학생 역량 관리 | M29: 혁신 | N29: 교육연구환경개선비 | O29: B-2 | P29: 251 | Q29: 2 | R29: 2 | S29: 3 | T29: ="NDZ251"&Q29&R29&S29 -> NDZ251223 | U29: 혁신B-2교육연구환경개선비 | V29: [B-2]AI 온디맨드 경력개발 지원체계 구축
E30: 원주박물관 | F30: 8752 | J30: 가. 포용역량 강화를 위한 RC 프로그램 고도화 | M30: 혁신 | N30: 인건비 | O30: B-2 | P30: 251 | Q30: 2 | R30: 2 | S30: 4 | T30: ="NDZ251"&Q30&R30&S30 -> NDZ251224 | U30: 혁신B-2인건비 | V30: [B-2]AI 온디맨드 경력개발 지원체계 구축 | W30: 부서사용불가
J31: 나. 공동체 기반 RC 참여·실천 활동 확대 | M31: 혁신 | N31: 장학금 | O31: B-2 | P31: 251 | Q31: 2 | R31: 2 | S31: 5 | T31: ="NDZ251"&Q31&R31&S31 -> NDZ251225 | U31: 혁신B-2장학금 | V31: [B-2]AI 온디맨드 경력개발 지원체계 구축
J32: 다. RC실천교육 성과 공유 및 비전 확산 | M32: 혁신 | N32: 그 밖의 사업운영 경비 | O32: B-2 | P32: 251 | Q32: 2 | R32: 2 | S32: 6 | T32: ="NDZ251"&Q32&R32&S32 -> NDZ251226 | U32: 혁신B-2그 밖의 사업운영 경비 | V32: [B-2]AI 온디맨드 경력개발 지원체계 구축 | W32: 부서사용불가
J33: 가. 신입생 진단 맞춤형 기초학습 시스템 연구 | M33: 혁신 | N33: 교육연구프로그램개발운영비 | O33: B-3 | P33: 251 | Q33: 2 | R33: 3 | S33: 1 | T33: ="NDZ251"&Q33&R33&S33 -> NDZ251231 | U33: 혁신B-3교육연구프로그램개발운영비 | V33: [B-3]마음건강 마이크로케어 플랫폼 고도화
J34: 나. 기초·교양 교육과정 체계 정비 및 다양화 | M34: 혁신 | N34: 실험실습장비및기자재구입비 | O34: B-3 | P34: 251 | Q34: 2 | R34: 3 | S34: 2 | T34: ="NDZ251"&Q34&R34&S34 -> NDZ251232 | U34: 혁신B-3실험실습장비및기자재구입비 | V34: [B-3]마음건강 마이크로케어 플랫폼 고도화
J35: 다. 데이터 기반 성과관리 및 환류 체계 강화 방안 연구 | M35: 혁신 | N35: 교육연구환경개선비 | O35: B-3 | P35: 251 | Q35: 2 | R35: 3 | S35: 3 | T35: ="NDZ251"&Q35&R35&S35 -> NDZ251233 | U35: 혁신B-3교육연구환경개선비 | V35: [B-3]마음건강 마이크로케어 플랫폼 고도화
J36: 가. 데이터 기반 전공·진로 탐색 체계 개선 | M36: 혁신 | N36: 인건비 | O36: B-3 | P36: 251 | Q36: 2 | R36: 3 | S36: 4 | T36: ="NDZ251"&Q36&R36&S36 -> NDZ251234 | U36: 혁신B-3인건비 | V36: [B-3]마음건강 마이크로케어 플랫폼 고도화 | W36: 부서사용불가
J37: 나. 전공·진로 탐색 경험 확대 | M37: 혁신 | N37: 장학금 | O37: B-3 | P37: 251 | Q37: 2 | R37: 3 | S37: 5 | T37: ="NDZ251"&Q37&R37&S37 -> NDZ251235 | U37: 혁신B-3장학금 | V37: [B-3]마음건강 마이크로케어 플랫폼 고도화
J38: 다. 맞춤형 진단을 통한 전공·교양 설계 고도화 | M38: 혁신 | N38: 그 밖의 사업운영 경비 | O38: B-3 | P38: 251 | Q38: 2 | R38: 3 | S38: 6 | T38: ="NDZ251"&Q38&R38&S38 -> NDZ251236 | U38: 혁신B-3그 밖의 사업운영 경비 | V38: [B-3]마음건강 마이크로케어 플랫폼 고도화 | W38: 부서사용불가
J39: 가. 교원 인사제도 개선 | M39: 혁신 | N39: 교육연구프로그램개발운영비 | O39: C-1 | P39: 251 | Q39: 3 | R39: 1 | S39: 1 | T39: ="NDZ251"&Q39&R39&S39 -> NDZ251311 | U39: 혁신C-1교육연구프로그램개발운영비 | V39: [C-1]AI 기반 교육과정 혁신 및 수업모델 개발
J40: 나. 학부(과) 성과평가제도 개선 | M40: 혁신 | N40: 실험실습장비및기자재구입비 | O40: C-1 | P40: 251 | Q40: 3 | R40: 1 | S40: 2 | T40: ="NDZ251"&Q40&R40&S40 -> NDZ251312 | U40: 혁신C-1실험실습장비및기자재구입비 | V40: [C-1]AI 기반 교육과정 혁신 및 수업모델 개발
J41: 가. 공유공간 확대를 통한 운영 효율화 | M41: 혁신 | N41: 교육연구환경개선비 | O41: C-1 | P41: 251 | Q41: 3 | R41: 1 | S41: 3 | T41: ="NDZ251"&Q41&R41&S41 -> NDZ251313 | U41: 혁신C-1교육연구환경개선비 | V41: [C-1]AI 기반 교육과정 혁신 및 수업모델 개발
...

Sheet 추경자료
A3: 행 레이블 | B3: 합계 : 최초예산 | D3: 행 레이블 | E3: 합계 : 최초예산 | G3: 예산내역 | I3: SAP
A4: 건축물관리비:기타 | B4: 671500000 | D4: 건축물관리비:기타 | E4: 671500000 | G4: =SUM(E4:F4) -> 671500000 | I4: 행 레이블 | J4: 합계 : 전체예산
A5: 교외장학금 | B5: 614469520 | D5: 교외장학금 | E5: 614469520 | G5: =SUM(E5:F5) -> 614469520 | I5: 건축물관리비:기타 | J5: 1142840000 | K5: =G4-J5 -> -471340000 | L5: =SUM(J5+K5) -> 671500000
A6: 교원급여/본봉 | B6: 800000000 | D6: 교원급여/본봉 | E6: 800000000 | G6: =SUM(E6:F6) -> 800000000 | I6: 교외장학금 | J6: 832485760 | K6: =G5-J6 -> -218016240 | L6: =SUM(J6+K6) -> 614469520
A7: 교원기타수당 | B7: 227500000 | D7: 교원기타수당 | E7: 227500000 | G7: =SUM(E7:F7) -> 227500000 | I7: 교원급여/본봉 | J7: 800000000 | L7: =SUM(J7+K7) -> 800000000
A8: 교육용기계기구구입지출 | B8: 82817652 | D8: 교육용기계기구구입지출 | E8: 82817652 | G8: =SUM(E8:F8) -> 82817652 | I8: 교원기타수당 | J8: 125300000 | K8: 74700000 | L8: =SUM(J8+K8) -> 200000000
A9: 교육용비품구입지출 | B9: 14520000 | D9: 교육용비품구입지출 | E9: 14520000 | G9: =SUM(E9:F9) -> 14520000 | I9: 교육용기계기구구입지출 | J9: 753810000 | K9: -650000000 | L9: =SUM(J9+K9) -> 103810000
A10: 기타운영비:부서별 | B10: 1762024400 | D10: 기타운영비:부서별 | E10: 1762024400 | F10: 1727000 | G10: =SUM(E10:F10) -> 1763751400 | I10: 교육용비품구입지출 | J10: 14520000 | K10: 0 | L10: =SUM(J10+K10) -> 14520000
A11: 소모품비:각부서 | B11: 7160000 | D11: 소모품비:각부서 | E11: 7160000 | G11: =SUM(E11:F11) -> 7160000 | I11: 기타운영비:부서별 | J11: 1133574310 | K11: 573479170 | L11: =SUM(J11+K11) -> 1707053480
A12: 업무용기계기구구입지출 | B12: 24113000 | D12: 업무용기계기구구입지출 | E12: 24113000 | G12: =SUM(E12:F12) -> 24113000 | I12: 비전임교원보험통합 | J12: 26790210 | L12: =SUM(J12+K12) -> 26790210
A13: 업무용비품구입지출 | B13: 11000000 | D13: 업무용비품구입지출 | E13: 11000000 | G13: =SUM(E13:F13) -> 11000000 | I13: 비전임교원수당 | J13: 10000000 | L13: =SUM(J13+K13) -> 10000000
A14: 일반용역비:부서별 | B14: 1568714000 | D14: 일반용역비:부서별 | E14: 1568714000 | G14: =SUM(E14:F14) -> 1568714000 | I14: 비전임교원인건비 | J14: 135678900 | L14: =SUM(J14+K14) -> 135678900
A15: 임시직/급여 | B15: 665500000 | D15: 임시직/급여 | E15: 665500000 | G15: =SUM(E15:F15) -> 665500000 | I15: 소모품비/부서별 | J15: 7160000 | K15: 0 | L15: =SUM(J15+K15) -> 7160000
A16: 임시직/급여:보험통합 | B16: 120000000 | D16: 임시직/급여:보험통합 | E16: 120000000 | F16: 5539291 | G16: =SUM(E16:F16) -> 125539291 | I16: 업무용기계기구구입지출 | J16: 35000000 | K16: -10000000 | L16: =SUM(J16+K16) -> 25000000 | N16: 임의조정
A17: 임시직수당:부서별 | B17: 60000000 | D17: 임시직수당:부서별 | E17: 60000000 | G17: =SUM(E17:F17) -> 60000000 | I17: 업무용비품구입지출 | J17: 35000000 | K17: -10000000 | L17: =SUM(J17+K17) -> 25000000
A18: 전기수도료:전기료 | B18: 530000000 | D18: 전기수도료:전기료 | E18: 530000000 | G18: =SUM(E18:F18) -> 530000000 | I18: 원주의대전출:기타 | J18: 2200000 | K18: 0 | L18: =SUM(J18+K18) -> 2200000
A19: 특별강의료:특별강의료 | B19: 8800000 | D19: 특별강의료:특별강의료 | E19: 8800000 | G19: =SUM(E19:F19) -> 8800000 | I19: 일반용역비:부서별 | J19: 1294536930 | K19: =G14-J19 -> 274177070 | L19: =SUM(J19+K19) -> 1568714000
A20: 행정사무직 수당 | B20: 70000000 | D20: 행정사무직 수당 | E20: 70000000 | G20: =SUM(E20:F20) -> 70000000 | I20: 임시직/급여 | J20: 557806500 | K20: -50000000 | L20: =SUM(J20+K20) -> 507806500
A21: 행정사무직수당:부서 | B21: 9000000 | D21: 행정사무직수당:부서 | E21: 9000000 | G21: =SUM(E21:F21) -> 9000000 | I21: 임시직/급여:보험통합 | J21: 47663980 | L21: =SUM(J21+K21) -> 47663980
A22: (비어 있음) | B22: 0 | G22: =SUM(E22:F22) -> 0 | I22: 임시직/수당 | J22: 45524773 | L22: =SUM(J22+K22) -> 45524773
A23: 총합계 | B23: 7247118572 | G23: =SUM(E23:F23) -> 0 | I23: 임시직_급량비 | J23: 30000000 | L23: =SUM(J23+K23) -> 30000000
G24: =SUM(E24:F24) -> 0 | I24: 임시직수당:부서별 | J24: 30000000 | L24: =SUM(J24+K24) -> 30000000
D25: (비어 있음) | E25: 0 | G25: =SUM(E25:F25) -> 0 | I25: 전기수도료:전기료 | J25: 500000000 | K25: 30000000 | L25: =SUM(J25+K25) -> 530000000
D26: 총합계 | E26: 7247118572 | F26: =SUM(F4:F25) -> 7266291 | G26: =SUM(E26:F26) -> 7254384863 | I26: 직원제수당:시간외수당 | J26: 10000000 | L26: =SUM(J26+K26) -> 10000000
I27: 직원퇴직:임시직퇴직 | J27: 12193500 | L27: =SUM(J27+K27) -> 12193500
I28: 특별강의료:특별강의료 | J28: 49700000 | L28: =SUM(J28+K28) -> 49700000
I29: 행정사무직 수당 | J29: 60000000 | K29: =G20-J29 -> 10000000 | L29: =SUM(J29+K29) -> 70000000
I30: 행정사무직수당:부서 | K30: =G21-J30 -> 9000000 | L30: =SUM(J30+K30) -> 9000000
I31: 총합계 | J31: =SUM(J5:J29) -> 7691784863 | K31: =SUM(K5:K30) -> -438000000 | L31: =J31+K31 -> 7253784863
I36: 2025년 반납이자 증액요청 | K36: 2033311
G37: =L31-G26 -> -600000

Sheet 성과관리위자료
A1: 2026년 대학혁신지원사업 사업비 배정 현황(2026.8.20. 기준)
A2: 세부과제 | B2: 부서 | C2: 추진내용 | D2: 배정예산 | E2: 선배정 | F2: 주요내용
A3: [A-1]AI기반 학사제도 다양화 | B3: 학사지원팀 | C3: 가. 전공 조합의 다양화를 통한 학사제도 고도화 | D3: 15300000 | E3: 14700000 | F3: 연구, 회의
C4: 나. 학생중심 과목개설 및 도전학기제 도입 | D4: 9750000 | E4: 9750000
C5: 다. 자기설계 전공 고도화 | D5: 4600000 | E5: 4600000
